Workbook

Sheet Sample-info
A1: ClientID | B1: Poochon ID | C1: Sample name | D1: Conc.(ug/ul) | E1: TMT-tag | F1: TMT set | G1: Group | H1: group2
A2: 1 | B2: 1 | C2: 001FEA | D2: 0.69142724 | E2: 126 | F2: set 1 | G2: a | H2: c | I2: 126
A3: 2 | B3: 2 | C3: 002FAA | D3: 0.51039477 | E3: 127N | G3: a | H3: d | I3: 127N
A4: 3 | B4: 3 | C4: 003MEA | D4: 0.61551039 | E4: 127C | G4: b | H4: c | I4: 127C
A5: 4 | B5: 4 | C5: 004FAA | D5: 0.51331465 | E5: 128N | G5: a | H5: d | I5: 128N
A6: 5 | B6: 5 | C6: 005FEA | D6: 0.48119598 | E6: 128C | G6: a | H6: c | I6: 128C
A7: 6 | B7: 6 | C7: 006FEA | D7: 0.39359963 | E7: 129N | G7: a | H7: c | I7: 129N
A8: 7 | B8: 7 | C8: 007FEA | D8: 0.51623452 | E8: 129C | G8: a | H8: c | I8: 129C
A9: 8 | B9: 8 | C9: 008MEA | D9: 0.51039477 | E9: 130N | G9: b | H9: c | I9: 130N
A10: 9 | B10: 9 | C10: 009FEA | D10: 0.55127307 | E10: 130C | G10: a | H10: c | I10: 130C
A11: 10 | B11: 10 | C11: 010MEA | D11: 0.48703574 | E11: 131N | G11: b | H11: c | I11: 131N
A12: 11 | B12: 11 | C12: 011FEA | D12: 0.91917776 | E12: 131C | G12: a | H12: c | I12: 131C
A13: 12 | B13: 12 | C13: 012FEA | D13: 1.2841626 | E13: 132N | G13: a | H13: c | I13: 132N
A14: 13 | B14: 13 | C14: 013MEA | D14: 0.80822238 | E14: 132C | G14: b | H14: c | I14: 132C
... A17: 16 | B17: 16 | C17: 016FEA | D17: 0.66806821 | E17: 134N | G17: a | H17: c | I17: 134N
C18: master mix1 | D18: master mix | E18: 134C | I18: 134C
A19: 17 | B19: 17 | C19: 017FEA | D19: 0.82282177 | E19: 126 | F19: set 2 | G19: a | H19: c | I19: 126
A20: 18 | B20: 18 | C20: 018MEA | D20: 0.84034104 | E20: 127N | G20: b | H20: c | I20: 127N
A21: 19 | B21: 19 | C21: 019MEA | D21: 0.78486335 | E21: 127C | G21: b | H21: c | I21: 127C
A22: 20 | B22: 20 | C22: 020MAA | D22: 0.51039477 | E22: 128N | G22: b | H22: d | I22: 128N
A23: 21 | B23: 21 | C23: 021MAA | D23: 0.67390797 | E23: 128C | G23: b | H23: d | I23: 128C
A24: 22 | B24: 22 | C24: 022MAA | D24: 0.59799112 | E24: 129N | G24: b | H24: d | I24: 129N
A25: 23 | B25: 23 | C25: 023MAA | D25: 0.95713618 | E25: 129C | G25: b | H25: d | I25: 129C
A26: 24 | B26: 24 | C26: 024FAA | D26: 0.74690493 | E26: 130N | G26: a | H26: d | I26: 130N
A27: 25 | B27: 25 | C27: 025FAA | D27: 0.94253679 | E27: 130C | G27: a | H27: d | I27: 130C
A28: 26 | B28: 26 | C28: 026MAA | D28: 0.9688157 | E28: 131N | G28: b | H28: d | I28: 131N
A29: 27 | B29: 27 | C29: 027FAA | D29: 0.63886942 | E29: 131C | G29: a | H29: d | I29: 131C
A30: 28 | B30: 28 | C30: 028FEA | D30: 0.75274469 | E30: 132N | G30: a | H30: c | I30: 132N
A31: 29 | B31: 29 | C31: 029FAA | D31: 0.81990189 | E31: 132C | G31: a | H31: d | I31: 132C
... A34: 32 | B34: 32 | C34: 032FAA | D34: 0.86078019 | E34: 134N | G34: a | H34: d | I34: 134N
C35: master mix2 | D35: master mix | E35: 134C | I35: 134C

Sheet Proteins
A1: Protein FDR Confidence: Combined | B1: Accession | C1: Description | D1: Exp. q-value: Combined | E1: Sum PEP Score | F1: Coverage [%] | G1: # Peptides | H1: # PSMs | I1: # Unique Peptides | J1: # AAs | K1: MW [kDa] | L1: calc. pI | M1: Score Sequest HT: Sequest HT | N1: # Peptides (by Search Engine): Sequest HT | O1: # Razor Peptides | P1: Abundance: F1: 126, Sample | Q1: Abundance: F1: 127N, Sample | R1: Abundance: F1: 127C, Sample | S1: Abundance: F1: 128N, Sample | T1: Abundance: F1: 128C, Sample | U1: Abundance: F1: 129N, Sample | V1: Abundance: F1: 129C, Sample | W1: Abundance: F1: 130N, Sample | X1: Abundance: F1: 130C, Sample | Y1: Abundance: F1: 131N, Sample | Z1: Abundance: F1: 131C, Sample | AA1: Abundance: F1: 132N, Sample | AB1: Abundance: F1: 132C, Sample | AC1: Abundance: F1: 133N, Sample | AD1: Abundance: F1: 133C, Sample | AE1: Abundance: F1: 134N, Sample | AF1: Abundance: F1: 134C, Sample | AG1: Abundance: F2: 126, Sample | AH1: Abundance: F2: 127N, Sample | AI1: Abundance: F2: 127C, Sample | AJ1: Abundance: F2: 128N, Sample | AK1: Abundance: F2: 128C, Sample | AL1: Abundance: F2: 129N, Sample | AM1: Abundance: F2: 129C, Sample | AN1: Abundance: F2: 130N, Sample | AO1: Abundance: F2: 130C, Sample | AP1: Abundance: F2: 131N, Sample | AQ1: Abundance: F2: 131C, Sample | AR1: Abundance: F2: 132N, Sample | AS1: Abundance: F2: 132C, Sample | AT1: Abundance: F2: 133N, Sample | AU1: Abundance: F2: 133C, Sample | AV1: Abundance: F2: 134N, Sample | AW1: Abundance: F2: 134C, Sample | AX1: Ratio(Abundance: F1: 126, Sample/F1: 134C, Sample) | AY1: Ratio(Abundance: F1: 127N, Sample/F1: 134C, Sample) | AZ1: Ratio(Abundance: F1: 127C, Sample/F1: 134C, Sample) | BA1: Ratio(Abundance: F1: 128N, Sample/F1: 134C, Sample) | BB1: Ratio(Abundance: F1: 128C, Sample/F1: 134C, Sample) | BC1: Ratio(Abundance: F1: 129N, Sample/F1: 134C, Sample) | BD1: Ratio(Abundance: F1: 129C, Sample/F1: 134C, Sample) | BE1: Ratio(Abundance: F1: 130N, Sample/F1: 134C, Sample) | BF1: Ratio(Abundance: F1: 130C, Sample/F1: 134C, Sample) | BG1: Ratio(Abundance: F1: 131N, Sample/F1: 134C, Sample) | BH1: Ratio(Abundance: F1: 131C, Sample/F1: 134C, Sample) | BI1: Ratio(Abundance: F1: 132N, Sample/F1: 134C, Sample) | BJ1: Ratio(Abundance: F1: 132C, Sample/F1: 134C, Sample) | BK1: Ratio(Abundance: F1: 133N, Sample/F1: 134C, Sample) | BL1: Ratio(Abundance: F1: 133C, Sample/F1: 134C, Sample) | BM1: Ratio(Abundance: F1: 134N, Sample/F1: 134C, Sample) | BN1: Ratio(Abundance: F1: 134C, Sample/F1: 134C, Sample) | BO1: Ratio(Abundance: F2: 126, Sample/F2: 134C, Sample) | BP1: Ratio(Abundance: F2: 127N, Sample/F2: 134C, Sample) | BQ1: Ratio(Abundance: F2: 127C, Sample/F2: 134C, Sample) | BR1: Ratio(Abundance: F2: 128N, Sample/F2: 134C, Sample) | BS1: Ratio(Abundance: F2: 128C, Sample/F2: 134C, Sample) | BT1: Ratio(Abundance: F2: 129N, Sample/F2: 134C, Sample) | BU1: Ratio(Abundance: F2: 129C, Sample/F2: 134C, Sample) | BV1: Ratio(Abundance: F2: 130N, Sample/F2: 134C, Sample) | BW1: Ratio(Abundance: F2: 130C, Sample/F2: 134C, Sample) | BX1: Ratio(Abundance: F2: 131N, Sample/F2: 134C, Sample) | BY1: Ratio(Abundance: F2: 131C, Sample/F2: 134C, Sample) | BZ1: Ratio(Abundance: F2: 132N, Sample/F2: 134C, Sample) | CA1: Ratio(Abundance: F2: 132C, Sample/F2: 134C, Sample) | CB1: Ratio(Abundance: F2: 133N, Sample/F2: 134C, Sample) | CC1: Ratio(Abundance: F2: 133C, Sample/F2: 134C, Sample) | CD1: Ratio(Abundance: F2: 134N, Sample/F2: 134C, Sample) | CE1: Ratio(Abundance: F2: 134C, Sample/F2: 134C, Sample) | CF1: Normalized Ratio(Abundance: F1: 126, Sample/F1: 134C, Sample) | CG1: Normalized Ratio(Abundance: F1: 127N, Sample/F1: 134C, Sample) | CH1: Normalized Ratio(Abundance: F1: 127C, Sample/F1: 134C, Sample) | CI1: Normalized Ratio(Abundance: F1: 128N, Sample/F1: 134C, Sample) | CJ1: Normalized Ratio(Abundance: F1: 128C, Sample/F1: 134C, Sample) | CK1: Normalized Ratio(Abundance: F1: 129N, Sample/F1: 134C, Sample) | CL1: Normalized Ratio(Abundance: F1: 129C, Sample/F1: 134C, Sample) | CM1: Normalized Ratio(Abundance: F1: 130N, Sample/F1: 134C, Sample) | CN1: Normalized Ratio(Abundance: F1: 130C, Sample/F1: 134C, Sample) | CO1: Normalized Ratio(Abundance: F1: 131N, Sample/F1: 134C, Sample) | CP1: Normalized Ratio(Abundance: F1: 131C, Sample/F1: 134C, Sample) | CQ1: Normalized Ratio(Abundance: F1: 132N, Sample/F1: 134C, Sample) | CR1: Normalized Ratio(Abundance: F1: 132C, Sample/F1: 134C, Sample) | CS1: Normalized Ratio(Abundance: F1: 133N, Sample/F1: 134C, Sample) | CT1: Normalized Ratio(Abundance: F1: 133C, Sample/F1: 134C, Sample) | CU1: Normalized Ratio(Abundance: F1: 134N, Sample/F1: 134C, Sample) | CV1: Normalized Ratio(Abundance: F1: 134C, Sample/F1: 134C, Sample) | CW1: Normalized Ratio(Abundance: F2: 126, Sample/F2: 134C, Sample) | CX1: Normalized Ratio(Abundance: F2: 127N, Sample/F2: 134C, Sample) | CY1: Normalized Ratio(Abundance: F2: 127C, Sample/F2: 134C, Sample) | CZ1: Normalized Ratio(Abundance: F2: 128N, Sample/F2: 134C, Sample) | DA1: Normalized Ratio(Abundance: F2: 128C, Sample/F2: 134C, Sample) | DB1: Normalized Ratio(Abundance: F2: 129N, Sample/F2: 134C, Sample) | DC1: Normalized Ratio(Abundance: F2: 129C, Sample/F2: 134C, Sample) | DD1: Normalized Ratio(Abundance: F2: 130N, Sample/F2: 134C, Sample) | DE1: Normalized Ratio(Abundance: F2: 130C, Sample/F2: 134C, Sample) | DF1: Normalized Ratio(Abundance: F2: 131N, Sample/F2: 134C, Sample) | DG1: Normalized Ratio(Abundance: F2: 131C, Sample/F2: 134C, Sample) | DH1: Normalized Ratio(Abundance: F2: 132N, Sample/F2: 134C, Sample) | DI1: Normalized Ratio(Abundance: F2: 132C, Sample/F2: 134C, Sample) | DJ1: Normalized Ratio(Abundance: F2: 133N, Sample/F2: 134C, Sample) | DK1: Normalized Ratio(Abundance: F2: 133C, Sample/F2: 134C, Sample) | DL1: Normalized Ratio(Abundance: F2: 134N, Sample/F2: 134C, Sample) | DM1: Normalized Ratio(Abundance: F2: 134C, Sample/F2: 134C, Sample)
A2: Low | B2: Q7RTR8 | C2: Taste receptor type 2 member 42 OS=Homo sapiens OX=9606 GN=TAS2R42 PE=2 SV=1 | D2: 0.192 | E2: 1.147 | F2: 3 | G2: 1 | H2: 45 | I2: 1 | J2: 314 | K2: 36.2 | L2: 9.6 | M2: 0 | N2: 1 | O2: 0 | AG2: 8.8 | AH2: 8.7 | AI2: 8.8 | AJ2: 11.1 | AK2: 9.1 | AL2: 9.1 | AM2: 11.6 | AN2: 14 | AO2: 10.2 | AP2: 10.5 | AQ2: 7.5 | AR2: 13.7 | AS2: 9 | AT2: 8.8 | AU2: 9.6 | AV2: 10.8 | AW2: 9.5 | AX2: 0 | AY2: 0 | AZ2: 0 | BA2: 0 | BB2: 0 | BC2: 0 | BD2: 0 | BE2: 0 | BF2: 0 | BG2: 0 | BH2: 0 | BI2: 0 | BJ2: 0 | BK2: 0 | BL2: 0 | BM2: 0 | BN2: 0 | BO2: =AG2/$AW2 -> 0.92631579 | BP2: =AH2/$AW2 -> 0.91578947 | BQ2: =AI2/$AW2 -> 0.92631579 | BR2: =AJ2/$AW2 -> 1.1684211 | BS2: =AK2/$AW2 -> 0.95789474 | BT2: =AL2/$AW2 -> 0.95789474 | BU2: =AM2/$AW2 -> 1.2210526 | BV2: =AN2/$AW2 -> 1.4736842 | ... CE2: =AW2/$AW2 -> 1 | CF2: =AX2*NF!B$6 -> 0 | CG2: =AY2*NF!C$6 -> 0 | CH2: =AZ2*NF!D$6 -> 0 | CI2: =BA2*NF!E$6 -> 0 | CJ2: =BB2*NF!F$6 -> 0 | CK2: =BC2*NF!G$6 -> 0 | CL2: =BD2*NF!H$6 -> 0 | CM2: =BE2*NF!I$6 -> 0 | ... DM2: =CE2*NF!AI$6 -> 1
A3: Low | B3: Q9NP81 | C3: Serine--tRNA ligase, mitochondrial OS=Homo sapiens OX=9606 GN=SARS2 PE=1 SV=1 | D3: 0.268 | E3: 0.829 | F3: 3 | G3: 1 | H3: 4 | I3: 1 | J3: 518 | K3: 58.2 | L3: 8.13 | M3: 0 | N3: 1 | O3: 0 | AG3: 10.5 | AH3: 12.9 | AI3: 8.4 | AJ3: 11.8 | AK3: 12 | AL3: 22.5 | AM3: 25.6 | AN3: 44.1 | AO3: 13.2 | AP3: 10.5 | AQ3: 9.8 | AR3: 7.6 | AS3: 8.4 | AT3: 10.5 | AU3: 8 | AV3: 9.6 | AW3: 8.8 | AX3: 0 | AY3: 0 | AZ3: 0 | BA3: 0 | BB3: 0 | BC3: 0 | BD3: 0 | BE3: 0 | BF3: 0 | BG3: 0 | BH3: 0 | BI3: 0 | BJ3: 0 | BK3: 0 | BL3: 0 | BM3: 0 | BN3: 0 | BO3: =AG3/$AW3 -> 1.1931818 | BP3: =AH3/$AW3 -> 1.4659091 | BQ3: =AI3/$AW3 -> 0.95454545 | BR3: =AJ3/$AW3 -> 1.3409091 | BS3: =AK3/$AW3 -> 1.3636364 | BT3: =AL3/$AW3 -> 2.5568182 | BU3: =AM3/$AW3 -> 2.9090909 | BV3: =AN3/$AW3 -> 5.0113636 | ... CE3: =AW3/$AW3 -> 1 | CF3: =AX3*NF!B$6 -> 0 | CG3: =AY3*NF!C$6 -> 0 | CH3: =AZ3*NF!D$6 -> 0 | CI3: =BA3*NF!E$6 -> 0 | CJ3: =BB3*NF!F$6 -> 0 | CK3: =BC3*NF!G$6 -> 0 | CL3: =BD3*NF!H$6 -> 0 | CM3: =BE3*NF!I$6 -> 0 | ... DM3: =CE3*NF!AI$6 -> 1
A4: High | B4: P04921 | C4: Glycophorin-C OS=Homo sapiens OX=9606 GN=GYPC PE=1 SV=1 | D4: 0 | E4: 9.969 | F4: 20 | G4: 1 | H4: 1 | I4: 1 | J4: 128 | K4: 13.8 | L4: 4.84 | M4: 5.45 | N4: 1 | O4: 0 | AG4: 11.4 | AH4: 15.5 | AI4: 13.8 | AJ4: 12.6 | AK4: 15.4 | AL4: 9.2 | AM4: 41.3 | AN4: 9.9 | AO4: 11.9 | AP4: 12.3 | AQ4: 11.5 | AR4: 6.5 | AS4: 8.7 | AT4: 10.7 | AU4: 11 | AV4: 14 | AW4: 9 | AX4: 0 | AY4: 0 | AZ4: 0 | BA4: 0 | BB4: 0 | BC4: 0 | BD4: 0 | BE4: 0 | BF4: 0 | BG4: 0 | BH4: 0 | BI4: 0 | BJ4: 0 | BK4: 0 | BL4: 0 | BM4: 0 | BN4: 0 | BO4: =AG4/$AW4 -> 1.2666667 | BP4: =AH4/$AW4 -> 1.7222222 | BQ4: =AI4/$AW4 -> 1.5333333 | BR4: =AJ4/$AW4 -> 1.4 | BS4: =AK4/$AW4 -> 1.7111111 | BT4: =AL4/$AW4 -> 1.0222222 | BU4: =AM4/$AW4 -> 4.5888889 | BV4: =AN4/$AW4 -> 1.1 | ... CE4: =AW4/$AW4 -> 1 | CF4: =AX4*NF!B$6 -> 0 | CG4: =AY4*NF!C$6 -> 0 | CH4: =AZ4*NF!D$6 -> 0 | CI4: =BA4*NF!E$6 -> 0 | CJ4: =BB4*NF!F$6 -> 0 | CK4: =BC4*NF!G$6 -> 0 | CL4: =BD4*NF!H$6 -> 0 | CM4: =BE4*NF!I$6 -> 0 | ... DM4: =CE4*NF!AI$6 -> 1
A5: Low | B5: P46777 | C5: 60S ribosomal protein L5 OS=Homo sapiens OX=9606 GN=RPL5 PE=1 SV=3 | D5: 0.209 | E5: 1.078 | F5: 7 | G5: 1 | H5: 1 | I5: 1 | J5: 297 | K5: 34.3 | L5: 9.72 | M5: 0 | N5: 1 | O5: 0 | AG5: 12.2 | AH5: 9.3 | AI5: 15.5 | AJ5: 8.4 | AK5: 10.8 | AL5: 11.2 | AM5: 15.9 | AN5: 12.5 | AO5: 8.1 | AP5: 10.1 | AQ5: 9.8 | AR5: 12.7 | AS5: 5.4 | AT5: 16.2 | AU5: 12.1 | AV5: 6 | AW5: 6.2 | AX5: 0 | AY5: 0 | AZ5: 0 | BA5: 0 | BB5: 0 | BC5: 0 | BD5: 0 | BE5: 0 | BF5: 0 | BG5: 0 | BH5: 0 | BI5: 0 | BJ5: 0 | BK5: 0 | BL5: 0 | BM5: 0 | BN5: 0 | BO5: =AG5/$AW5 -> 1.9677419 | BP5: =AH5/$AW5 -> 1.5 | BQ5: =AI5/$AW5 -> 2.5 | BR5: =AJ5/$AW5 -> 1.3548387 | BS5: =AK5/$AW5 -> 1.7419355 | BT5: =AL5/$AW5 -> 1.8064516 | BU5: =AM5/$AW5 -> 2.5645161 | BV5: =AN5/$AW5 -> 2.016129 | ... CE5: =AW5/$AW5 -> 1 | CF5: =AX5*NF!B$6 -> 0 | CG5: =AY5*NF!C$6 -> 0 | CH5: =AZ5*NF!D$6 -> 0 | CI5: =BA5*NF!E$6 -> 0 | CJ5: =BB5*NF!F$6 -> 0 | CK5: =BC5*NF!G$6 -> 0 | CL5: =BD5*NF!H$6 -> 0 | CM5: =BE5*NF!I$6 -> 0 | ... DM5: =CE5*NF!AI$6 -> 1
A6: High | B6: Q3ZCW2 | C6: Galectin-related protein OS=Homo sapiens OX=9606 GN=LGALSL PE=1 SV=2 | D6: 0.001 | E6: 5.422 | F6: 21 | G6: 3 | H6: 3 | I6: 3 | J6: 172 | K6: 19 | L6: 5.35 | M6: 2.12 | N6: 3 | O6: 0 | P6: 232.6 | Q6: 116.3 | R6: 146.5 | S6: 244.2 | T6: 194.1 | U6: 227.6 | V6: 260.5 | W6: 245.5 | X6: 134.8 | Y6: 194.7 | Z6: 196.6 | AA6: 178.1 | AB6: 96.1 | AC6: 153.3 | AD6: 152.3 | AE6: 206.5 | AF6: 129.9 | AG6: 12.6 | AH6: 13.2 | AI6: 13.5 | AJ6: 8.8 | AK6: 11.9 | AL6: 25.3 | AM6: 18.5 | AN6: 12 | AO6: 7.1 | AP6: 9 | AQ6: 6.9 | AR6: 6.6 | AS6: 9.6 | AT6: 8.2 | AU6: 10 | AV6: 12.6 | AW6: 15.4 | AX6: =P6/$AF6 -> 1.7906082 | AY6: =Q6/$AF6 -> 0.89530408 | AZ6: =R6/$AF6 -> 1.1277906 | BA6: =S6/$AF6 -> 1.8799076 | BB6: =T6/$AF6 -> 1.4942263 | BC6: =U6/$AF6 -> 1.752117 | BD6: =V6/$AF6 -> 2.0053888 | BE6: =W6/$AF6 -> 1.8899153 | ... BN6: =AF6/$AF6 -> 1 | BO6: =AG6/$AW6 -> 0.81818182 | BP6: =AH6/$AW6 -> 0.85714286 | BQ6: =AI6/$AW6 -> 0.87662338 | BR6: =AJ6/$AW6 -> 0.57142857 | BS6: =AK6/$AW6 -> 0.77272727 | BT6: =AL6/$AW6 -> 1.6428571 | BU6: =AM6/$AW6 -> 1.2012987 | BV6: =AN6/$AW6 -> 0.77922078 | ... CE6: =AW6/$AW6 -> 1 | CF6: =AX6*NF!B$6 -> 1.832906 | CG6: =AY6*NF!C$6 -> 0.80509576 | CH6: =AZ6*NF!D$6 -> 1.0237241 | CI6: =BA6*NF!E$6 -> 1.5637454 | CJ6: =BB6*NF!F$6 -> 1.2021926 | CK6: =BC6*NF!G$6 -> 1.3016766 | CL6: =BD6*NF!H$6 -> 1.4521028 | CM6: =BE6*NF!I$6 -> 1.5338178 | ... DM6: =CE6*NF!AI$6 -> 1
A7: High | B7: Q9UMD9 | C7: Collagen alpha-1(XVII) chain OS=Homo sapiens OX=9606 GN=COL17A1 PE=1 SV=3 | D7: 0.001 | E7: 5.751 | F7: 1 | G7: 1 | H7: 2 | I7: 1 | J7: 1497 | K7: 150.3 | L7: 8.79 | M7: 6.92 | N7: 1 | O7: 0 | P7: 47.5 | Q7: 52.1 | R7: 65.9 | S7: 41.3 | T7: 119.4 | U7: 52.2 | V7: 48.8 | W7: 64 | X7: 34.8 | Y7: 71.5 | Z7: 51 | AA7: 45.6 | AB7: 25.5 | AC7: 51.1 | AD7: 42 | AE7: 54.2 | AF7: 52 | AG7: 12.8 | AH7: 13.6 | AI7: 12.2 | AJ7: 14.8 | AK7: 17.2 | AL7: 10 | AM7: 16.8 | AN7: 16.1 | AO7: 17.8 | AP7: 24.4 | AQ7: 4.5 | AR7: 8.6 | AS7: 5.9 | AT7: 5 | AU7: 20.5 | AV7: 11 | AW7: 12.1 | AX7: =P7/$AF7 -> 0.91346154 | AY7: =Q7/$AF7 -> 1.0019231 | AZ7: =R7/$AF7 -> 1.2673077 | BA7: =S7/$AF7 -> 0.79423077 | BB7: =T7/$AF7 -> 2.2961538 | BC7: =U7/$AF7 -> 1.0038462 | BD7: =V7/$AF7 -> 0.93846154 | BE7: =W7/$AF7 -> 1.2307692 | ... BN7: =AF7/$AF7 -> 1 | BO7: =AG7/$AW7 -> 1.0578512 | BP7: =AH7/$AW7 -> 1.1239669 | BQ7: =AI7/$AW7 -> 1.0082645 | BR7: =AJ7/$AW7 -> 1.2231405 | BS7: =AK7/$AW7 -> 1.4214876 | BT7: =AL7/$AW7 -> 0.82644628 | BU7: =AM7/$AW7 -> 1.3884298 | BV7: =AN7/$AW7 -> 1.3305785 | ... CE7: =AW7/$AW7 -> 1 | CF7: =AX7*NF!B$6 -> 0.93503938 | CG7: =AY7*NF!C$6 -> 0.90097213 | CH7: =AZ7*NF!D$6 -> 1.1503673 | CI7: =BA7*NF!E$6 -> 0.6606573 | CJ7: =BB7*NF!F$6 -> 1.8473902 | CK7: =BC7*NF!G$6 -> 0.74577387 | CL7: =BD7*NF!H$6 -> 0.67954035 | CM7: =BE7*NF!I$6 -> 0.99886792 | ... DM7: =CE7*NF!AI$6 -> 1
A8: Low | B8: A0A584 | C8: T cell receptor beta variable 11-2 OS=Homo sapiens OX=9606 GN=TRBV11-2 PE=3 SV=1 | D8: 0.255 | E8: 0.88 | F8: 24 | G8: 1 | H8: 4 | I8: 1 | J8: 115 | K8: 12.7 | L8: 8.16 | M8: 0 | N8: 1 | O8: 0 | AG8: 12.8 | AH8: 19.9 | AI8: 15.4 | AJ8: 16.3 | AK8: 12.6 | AL8: 11.5 | AM8: 11.1 | AN8: 16.6 | AO8: 11.6 | AP8: 20.3 | AQ8: 15.9 | AR8: 14.3 | AS8: 12.9 | AT8: 14 | AU8: 10.8 | AV8: 14.1 | AW8: 18.1 | AX8: 0 | AY8: 0 | AZ8: 0 | BA8: 0 | BB8: 0 | BC8: 0 | BD8: 0 | BE8: 0 | BF8: 0 | BG8: 0 | BH8: 0 | BI8: 0 | BJ8: 0 | BK8: 0 | BL8: 0 | BM8: 0 | BN8: 0 | BO8: =AG8/$AW8 -> 0.70718232 | BP8: =AH8/$AW8 -> 1.0994475 | BQ8: =AI8/$AW8 -> 0.85082873 | BR8: =AJ8/$AW8 -> 0.90055249 | BS8: =AK8/$AW8 -> 0.6961326 | BT8: =AL8/$AW8 -> 0.63535912 | BU8: =AM8/$AW8 -> 0.61325967 | BV8: =AN8/$AW8 -> 0.91712707 | ... CE8: =AW8/$AW8 -> 1 | CF8: =AX8*NF!B$6 -> 0 | CG8: =AY8*NF!C$6 -> 0 | CH8: =AZ8*NF!D$6 -> 0 | CI8: =BA8*NF!E$6 -> 0 | CJ8: =BB8*NF!F$6 -> 0 | CK8: =BC8*NF!G$6 -> 0 | CL8: =BD8*NF!H$6 -> 0 | CM8: =BE8*NF!I$6 -> 0 | ... DM8: =CE8*NF!AI$6 -> 1
A9: Low | B9: Q9UL16 | C9: Cilia- and flagella-associated protein 45 OS=Homo sapiens OX=9606 GN=CFAP45 PE=1 SV=2 | D9: 0.233 | E9: 0.977 | F9: 4 | G9: 1 | H9: 2 | I9: 1 | J9: 551 | K9: 65.7 | L9: 8.9 | M9: 0 | N9: 1 | O9: 0 | AG9: 13.2 | AH9: 16.2 | AI9: 15.1 | AJ9: 23.5 | AK9: 19.9 | AL9: 13.4 | AM9: 16.6 | AN9: 16.6 | AO9: 18.2 | AP9: 12.7 | AQ9: 12.8 | AR9: 8.7 | AS9: 10.4 | AT9: 12.7 | AU9: 9.2 | AV9: 18 | AW9: 16.5 | AX9: 0 | AY9: 0 | AZ9: 0 | BA9: 0 | BB9: 0 | BC9: 0 | BD9: 0 | BE9: 0 | BF9: 0 | BG9: 0 | BH9: 0 | BI9: 0 | BJ9: 0 | BK9: 0 | BL9: 0 | BM9: 0 | BN9: 0 | BO9: =AG9/$AW9 -> 0.8 | BP9: =AH9/$AW9 -> 0.98181818 | BQ9: =AI9/$AW9 -> 0.91515152 | BR9: =AJ9/$AW9 -> 1.4242424 | BS9: =AK9/$AW9 -> 1.2060606 | BT9: =AL9/$AW9 -> 0.81212121 | BU9: =AM9/$AW9 -> 1.0060606 | BV9: =AN9/$AW9 -> 1.0060606 | ... CE9: =AW9/$AW9 -> 1 | CF9: =AX9*NF!B$6 -> 0 | CG9: =AY9*NF!C$6 -> 0 | CH9: =AZ9*NF!D$6 -> 0 | CI9: =BA9*NF!E$6 -> 0 | CJ9: =BB9*NF!F$6 -> 0 | CK9: =BC9*NF!G$6 -> 0 | CL9: =BD9*NF!H$6 -> 0 | CM9: =BE9*NF!I$6 -> 0 | ... DM9: =CE9*NF!AI$6 -> 1
A10: Low | B10: Q8TDD5 | C10: Mucolipin-3 OS=Homo sapiens OX=9606 GN=MCOLN3 PE=1 SV=1 | D10: 0.203 | E10: 1.108 | F10: 4 | G10: 1 | H10: 2 | I10: 1 | J10: 553 | K10: 64.2 | L10: 6.18 | M10: 0 | N10: 1 | O10: 0 | AG10: 13.8 | AH10: 14.3 | AI10: 10.9 | AJ10: 10.3 | AK10: 11.9 | AL10: 8.3 | AM10: 7.8 | AN10: 8.8 | AO10: 8.5 | AP10: 9.5 | AQ10: 9.2 | AR10: 11.3 | AS10: 10.4 | AT10: 15.2 | AU10: 7.1 | AV10: 10.1 | AW10: 8.6 | AX10: 0 | AY10: 0 | AZ10: 0 | BA10: 0 | BB10: 0 | BC10: 0 | BD10: 0 | BE10: 0 | BF10: 0 | BG10: 0 | BH10: 0 | BI10: 0 | BJ10: 0 | BK10: 0 | BL10: 0 | BM10: 0 | BN10: 0 | BO10: =AG10/$AW10 -> 1.6046512 | BP10: =AH10/$AW10 -> 1.6627907 | BQ10: =AI10/$AW10 -> 1.2674419 | BR10: =AJ10/$AW10 -> 1.1976744 | BS10: =AK10/$AW10 -> 1.3837209 | BT10: =AL10/$AW10 -> 0.96511628 | BU10: =AM10/$AW10 -> 0.90697674 | BV10: =AN10/$AW10 -> 1.0232558 | ... CE10: =AW10/$AW10 -> 1 | CF10: =AX10*NF!B$6 -> 0 | CG10: =AY10*NF!C$6 -> 0 | CH10: =AZ10*NF!D$6 -> 0 | CI10: =BA10*NF!E$6 -> 0 | CJ10: =BB10*NF!F$6 -> 0 | CK10: =BC10*NF!G$6 -> 0 | CL10: =BD10*NF!H$6 -> 0 | CM10: =BE10*NF!I$6 -> 0 | ... DM10: =CE10*NF!AI$6 -> 1
A11: Low | B11: P30044 | C11: Peroxiredoxin-5, mitochondrial OS=Homo sapiens OX=9606 GN=PRDX5 PE=1 SV=4 | D11: 0.062 | E11: 2.005 | F11: 8 | G11: 1 | H11: 1 | I11: 1 | J11: 214 | K11: 22.1 | L11: 8.7 | M11: 0 | N11: 1 | O11: 0 | AG11: 13.9 | AH11: 13 | AI11: 14 | AJ11: 14.5 | AK11: 12.8 | AL11: 11 | AM11: 10.7 | AN11: 7.4 | AO11: 10.1 | AP11: 9.7 | AQ11: 10.1 | AR11: 15 | AS11: 9.4 | AT11: 10.7 | AU11: 8.9 | AV11: 14.9 | AW11: 8.5 | AX11: 0 | AY11: 0 | AZ11: 0 | BA11: 0 | BB11: 0 | BC11: 0 | BD11: 0 | BE11: 0 | BF11: 0 | BG11: 0 | BH11: 0 | BI11: 0 | BJ11: 0 | BK11: 0 | BL11: 0 | BM11: 0 | BN11: 0 | BO11: =AG11/$AW11 -> 1.6352941 | BP11: =AH11/$AW11 -> 1.5294118 | BQ11: =AI11/$AW11 -> 1.6470588 | BR11: =AJ11/$AW11 -> 1.7058824 | BS11: =AK11/$AW11 -> 1.5058824 | BT11: =AL11/$AW11 -> 1.2941176 | BU11: =AM11/$AW11 -> 1.2588235 | BV11: =AN11/$AW11 -> 0.87058824 | ... CE11: =AW11/$AW11 -> 1 | CF11: =AX11*NF!B$6 -> 0 | CG11: =AY11*NF!C$6 -> 0 | CH11: =AZ11*NF!D$6 -> 0 | CI11: =BA11*NF!E$6 -> 0 | CJ11: =BB11*NF!F$6 -> 0 | CK11: =BC11*NF!G$6 -> 0 | CL11: =BD11*NF!H$6 -> 0 | CM11: =BE11*NF!I$6 -> 0 | ... DM11: =CE11*NF!AI$6 -> 1
A12: Low | B12: Q9NYC9 | C12: Dynein heavy chain 9, axonemal OS=Homo sapiens OX=9606 GN=DNAH9 PE=1 SV=3 | D12: 0.244 | E12: 0.93 | F12: 0 | G12: 1 | H12: 2 | I12: 1 | J12: 4486 | K12: 511.6 | L12: 5.91 | M12: 0 | N12: 1 | O12: 0 | AG12: 15.8 | AH12: 15.2 | AI12: 14.5 | AJ12: 14.7 | AK12: 21.6 | AL12: 14.8 | AM12: 15.5 | AN12: 15.5 | AO12: 15 | AP12: 17.9 | AQ12: 13 | AR12: 14.5 | AS12: 15.5 | AT12: 17.5 | AU12: 12.3 | AV12: 14.4 | AW12: 10.8 | AX12: 0 | AY12: 0 | AZ12: 0 | BA12: 0 | BB12: 0 | BC12: 0 | BD12: 0 | BE12: 0 | BF12: 0 | BG12: 0 | BH12: 0 | BI12: 0 | BJ12: 0 | BK12: 0 | BL12: 0 | BM12: 0 | BN12: 0 | BO12: =AG12/$AW12 -> 1.462963 | BP12: =AH12/$AW12 -> 1.4074074 | BQ12: =AI12/$AW12 -> 1.3425926 | BR12: =AJ12/$AW12 -> 1.3611111 | BS12: =AK12/$AW12 -> 2 | BT12: =AL12/$AW12 -> 1.3703704 | BU12: =AM12/$AW12 -> 1.4351852 | BV12: =AN12/$AW12 -> 1.4351852 | ... CE12: =AW12/$AW12 -> 1 | CF12: =AX12*NF!B$6 -> 0 | CG12: =AY12*NF!C$6 -> 0 | CH12: =AZ12*NF!D$6 -> 0 | CI12: =BA12*NF!E$6 -> 0 | CJ12: =BB12*NF!F$6 -> 0 | CK12: =BC12*NF!G$6 -> 0 | CL12: =BD12*NF!H$6 -> 0 | CM12: =BE12*NF!I$6 -> 0 | ... DM12: =CE12*NF!AI$6 -> 1
A13: Medium | B13: P25391 | C13: Laminin subunit alpha-1 OS=Homo sapiens OX=9606 GN=LAMA1 PE=1 SV=2 | D13: 0.02 | E13: 3.235 | F13: 1 | G13: 2 | H13: 10 | I13: 1 | J13: 3075 | K13: 336.9 | L13: 6.35 | M13: 2.04 | N13: 2 | O13: 0 | AG13: 16 | AH13: 16.6 | AI13: 11.6 | AJ13: 13.6 | AK13: 14.6 | AL13: 12.2 | AM13: 8.9 | AN13: 10.6 | AO13: 16.1 | AP13: 13.1 | AQ13: 13.3 | AR13: 18.5 | AS13: 12.9 | AT13: 19 | AU13: 12.2 | AV13: 13.7 | AW13: 8.8 | AX13: 0 | AY13: 0 | AZ13: 0 | BA13: 0 | BB13: 0 | BC13: 0 | BD13: 0 | BE13: 0 | BF13: 0 | BG13: 0 | BH13: 0 | BI13: 0 | BJ13: 0 | BK13: 0 | BL13: 0 | BM13: 0 | BN13: 0 | BO13: =AG13/$AW13 -> 1.8181818 | BP13: =AH13/$AW13 -> 1.8863636 | BQ13: =AI13/$AW13 -> 1.3181818 | BR13: =AJ13/$AW13 -> 1.5454545 | BS13: =AK13/$AW13 -> 1.6590909 | BT13: =AL13/$AW13 -> 1.3863636 | BU13: =AM13/$AW13 -> 1.0113636 | BV13: =AN13/$AW13 -> 1.2045455 | ... CE13: =AW13/$AW13 -> 1 | CF13: =AX13*NF!B$6 -> 0 | CG13: =AY13*NF!C$6 -> 0 | CH13: =AZ13*NF!D$6 -> 0 | CI13: =BA13*NF!E$6 -> 0 | CJ13: =BB13*NF!F$6 -> 0 | CK13: =BC13*NF!G$6 -> 0 | CL13: =BD13*NF!H$6 -> 0 | CM13: =BE13*NF!I$6 -> 0 | ... DM13: =CE13*NF!AI$6 -> 1
A14: Low | B14: Q86V48 | C14: Leucine zipper protein 1 OS=Homo sapiens OX=9606 GN=LUZP1 PE=1 SV=2 | D14: 0.198 | E14: 1.128 | F14: 1 | G14: 1 | H14: 1 | I14: 1 | J14: 1076 | K14: 120.2 | L14: 8.5 | M14: 0 | N14: 1 | O14: 0 | AG14: 16.9 | AH14: 29.5 | AI14: 23.4 | AJ14: 25.6 | AK14: 20.6 | AL14: 53.9 | AM14: 22.4 | AN14: 140.7 | AO14: 40.7 | AP14: 30 | AQ14: 31.6 | AR14: 21.5 | AS14: 15.9 | AT14: 29.8 | AU14: 21.8 | AV14: 24 | AW14: 22.5 | AX14: 0 | AY14: 0 | AZ14: 0 | BA14: 0 | BB14: 0 | BC14: 0 | BD14: 0 | BE14: 0 | BF14: 0 | BG14: 0 | BH14: 0 | BI14: 0 | BJ14: 0 | BK14: 0 | BL14: 0 | BM14: 0 | BN14: 0 | BO14: =AG14/$AW14 -> 0.75111111 | BP14: =AH14/$AW14 -> 1.3111111 | BQ14: =AI14/$AW14 -> 1.04 | BR14: =AJ14/$AW14 -> 1.1377778 | BS14: =AK14/$AW14 -> 0.91555556 | BT14: =AL14/$AW14 -> 2.3955556 | BU14: =AM14/$AW14 -> 0.99555556 | BV14: =AN14/$AW14 -> 6.2533333 | ... CE14: =AW14/$AW14 -> 1 | CF14: =AX14*NF!B$6 -> 0 | CG14: =AY14*NF!C$6 -> 0 | CH14: =AZ14*NF!D$6 -> 0 | CI14: =BA14*NF!E$6 -> 0 | CJ14: =BB14*NF!F$6 -> 0 | CK14: =BC14*NF!G$6 -> 0 | CL14: =BD14*NF!H$6 -> 0 | CM14: =BE14*NF!I$6 -> 0 | ... DM14: =CE14*NF!AI$6 -> 1
A15: Medium | B15: Q9H3U7 | C15: SPARC-related modular calcium-binding protein 2 OS=Homo sapiens OX=9606 GN=SMOC2 PE=1 SV=2 | D15: 0.037 | E15: 2.487 | F15: 2 | G15: 1 | H15: 2 | I15: 1 | J15: 446 | K15: 49.6 | L15: 8.46 | M15: 4.74 | N15: 1 | O15: 0 | P15: 11.5 | Q15: 24.8 | R15: 18.7 | S15: 22.3 | T15: 20.7 | U15: 37.6 | V15: 33.5 | W15: 24.8 | X15: 32.8 | Y15: 18.2 | Z15: 35.8 | AA15: 22.4 | AB15: 17.9 | AC15: 16.6 | AD15: 19.1 | AE15: 18.3 | AF15: 24.7 | AG15: 17 | AH15: 22.9 | AI15: 13.4 | AJ15: 37.9 | AK15: 34.3 | AL15: 21.6 | AM15: 36.5 | AN15: 19.4 | AO15: 16.9 | AP15: 17.2 | AQ15: 21.9 | AR15: 14.7 | AS15: 16.8 | AT15: 16.4 | AU15: 25 | AV15: 22.6 | AW15: 27.6 | AX15: =P15/$AF15 -> 0.46558704 | AY15: =Q15/$AF15 -> 1.0040486 | AZ15: =R15/$AF15 -> 0.75708502 | BA15: =S15/$AF15 -> 0.90283401 | BB15: =T15/$AF15 -> 0.83805668 | BC15: =U15/$AF15 -> 1.5222672 | BD15: =V15/$AF15 -> 1.3562753 | BE15: =W15/$AF15 -> 1.0040486 | ... BN15: =AF15/$AF15 -> 1 | BO15: =AG15/$AW15 -> 0.61594203 | BP15: =AH15/$AW15 -> 0.82971014 | BQ15: =AI15/$AW15 -> 0.48550725 | BR15: =AJ15/$AW15 -> 1.3731884 | BS15: =AK15/$AW15 -> 1.2427536 | BT15: =AL15/$AW15 -> 0.7826087 | BU15: =AM15/$AW15 -> 1.3224638 | BV15: =AN15/$AW15 -> 0.70289855 | ... CE15: =AW15/$AW15 -> 1 | CF15: =AX15*NF!B$6 -> 0.47658517 | CG15: =AY15*NF!C$6 -> 0.90288347 | CH15: =AZ15*NF!D$6 -> 0.68722524 | CI15: =BA15*NF!E$6 -> 0.75099568 | CJ15: =BB15*NF!F$6 -> 0.67426567 | CK15: =BC15*NF!G$6 -> 1.1309174 | CL15: =BD15*NF!H$6 -> 0.98207946 | CM15: =BE15*NF!I$6 -> 0.81486594 | ... DM15: =CE15*NF!AI$6 -> 1
A16: Low | B16: Q96NJ5 | C16: Kelch-like protein 32 OS=Homo sapiens OX=9606 GN=KLHL32 PE=2 SV=2 | D16: 0.256 | E16: 0.878 | F16: 2 | G16: 1 | H16: 1 | I16: 1 | J16: 620 | K16: 70.3 | L16: 6.42 | M16: 0 | N16: 1 | O16: 0 | AG16: 17.8 | AH16: 27.5 | AI16: 14.5 | AJ16: 22.4 | AK16: 20.9 | AL16: 15.5 | AM16: 14.6 | AN16: 15.6 | AO16: 15.1 | AP16: 15.3 | AQ16: 17.5 | AR16: 15 | AS16: 13.1 | AT16: 19.9 | AU16: 12.6 | AV16: 15.3 | AW16: 22.8 | AX16: 0 | AY16: 0 | AZ16: 0 | BA16: 0 | BB16: 0 | BC16: 0 | BD16: 0 | BE16: 0 | BF16: 0 | BG16: 0 | BH16: 0 | BI16: 0 | BJ16: 0 | BK16: 0 | BL16: 0 | BM16: 0 | BN16: 0 | BO16: =AG16/$AW16 -> 0.78070175 | BP16: =AH16/$AW16 -> 1.2061404 | BQ16: =AI16/$AW16 -> 0.63596491 | BR16: =AJ16/$AW16 -> 0.98245614 | BS16: =AK16/$AW16 -> 0.91666667 | BT16: =AL16/$AW16 -> 0.67982456 | BU16: =AM16/$AW16 -> 0.64035088 | BV16: =AN16/$AW16 -> 0.68421053 | ... CE16: =AW16/$AW16 -> 1 | CF16: =AX16*NF!B$6 -> 0 | CG16: =AY16*NF!C$6 -> 0 | CH16: =AZ16*NF!D$6 -> 0 | CI16: =BA16*NF!E$6 -> 0 | CJ16: =BB16*NF!F$6 -> 0 | CK16: =BC16*NF!G$6 -> 0 | CL16: =BD16*NF!H$6 -> 0 | CM16: =BE16*NF!I$6 -> 0 | ... DM16: =CE16*NF!AI$6 -> 1
A17: Low | B17: Q96QT4 | C17: Transient receptor potential cation channel subfamily M member 7 OS=Homo sapiens OX=9606 GN=TRPM7 PE=1 SV=1 | D17: 0.267 | E17: 0.842 | F17: 2 | G17: 1 | H17: 1 | I17: 1 | J17: 1865 | K17: 212.6 | L17: 7.88 | M17: 0 | N17: 1 | O17: 0 | AG17: 19.5 | AH17: 25.7 | AI17: 23.3 | AJ17: 18.1 | AK17: 32.8 | AL17: 23.1 | AM17: 29.4 | AN17: 25.7 | AO17: 17.4 | AP17: 29.1 | AQ17: 24.1 | AR17: 22.7 | AS17: 25.1 | AT17: 27.8 | AU17: 26 | AV17: 21.3 | AW17: 23.1 | AX17: 0 | AY17: 0 | AZ17: 0 | BA17: 0 | BB17: 0 | BC17: 0 | BD17: 0 | BE17: 0 | BF17: 0 | BG17: 0 | BH17: 0 | BI17: 0 | BJ17: 0 | BK17: 0 | BL17: 0 | BM17: 0 | BN17: 0 | BO17: =AG17/$AW17 -> 0.84415584 | BP17: =AH17/$AW17 -> 1.1125541 | BQ17: =AI17/$AW17 -> 1.008658 | BR17: =AJ17/$AW17 -> 0.78354978 | BS17: =AK17/$AW17 -> 1.4199134 | BT17: =AL17/$AW17 -> 1 | BU17: =AM17/$AW17 -> 1.2727273 | BV17: =AN17/$AW17 -> 1.1125541 | ... CE17: =AW17/$AW17 -> 1 | CF17: =AX17*NF!B$6 -> 0 | CG17: =AY17*NF!C$6 -> 0 | CH17: =AZ17*NF!D$6 -> 0 | CI17: =BA17*NF!E$6 -> 0 | CJ17: =BB17*NF!F$6 -> 0 | CK17: =BC17*NF!G$6 -> 0 | CL17: =BD17*NF!H$6 -> 0 | CM17: =BE17*NF!I$6 -> 0 | ... DM17: =CE17*NF!AI$6 -> 1
A18: Low | B18: Q6QNK2 | C18: Adhesion G-protein coupled receptor D1 OS=Homo sapiens OX=9606 GN=ADGRD1 PE=1 SV=1 | D18: 0.183 | E18: 1.171 | F18: 1 | G18: 1 | H18: 1 | I18: 1 | J18: 874 | K18: 96.5 | L18: 7.88 | M18: 1.74 | N18: 1 | O18: 0 | AG18: 20.5 | AH18: 23.4 | AI18: 22.7 | AJ18: 20.1 | AK18: 50 | AL18: 33.6 | AM18: 34 | AN18: 19.7 | AO18: 24.1 | AP18: 31.9 | AQ18: 20.6 | AR18: 18.2 | AS18: 24.2 | AT18: 15.1 | AU18: 23.7 | AV18: 22.2 | AW18: 18.8 | AX18: 0 | AY18: 0 | AZ18: 0 | BA18: 0 | BB18: 0 | BC18: 0 | BD18: 0 | BE18: 0 | BF18: 0 | BG18: 0 | BH18: 0 | BI18: 0 | BJ18: 0 | BK18: 0 | BL18: 0 | BM18: 0 | BN18: 0 | BO18: =AG18/$AW18 -> 1.0904255 | BP18: =AH18/$AW18 -> 1.2446809 | BQ18: =AI18/$AW18 -> 1.2074468 | BR18: =AJ18/$AW18 -> 1.0691489 | BS18: =AK18/$AW18 -> 2.6595745 | BT18: =AL18/$AW18 -> 1.787234 | BU18: =AM18/$AW18 -> 1.8085106 | BV18: =AN18/$AW18 -> 1.0478723 | ... CE18: =AW18/$AW18 -> 1 | CF18: =AX18*NF!B$6 -> 0 | CG18: =AY18*NF!C$6 -> 0 | CH18: =AZ18*NF!D$6 -> 0 | CI18: =BA18*NF!E$6 -> 0 | CJ18: =BB18*NF!F$6 -> 0 | CK18: =BC18*NF!G$6 -> 0 | CL18: =BD18*NF!H$6 -> 0 | CM18: =BE18*NF!I$6 -> 0 | ... DM18: =CE18*NF!AI$6 -> 1
A19: Low | B19: Q5TC84 | C19: Opioid growth factor receptor-like protein 1 OS=Homo sapiens OX=9606 GN=OGFRL1 PE=2 SV=1 | D19: 0.173 | E19: 1.201 | F19: 4 | G19: 1 | H19: 1 | I19: 1 | J19: 451 | K19: 51.2 | L19: 6.13 | M19: 0 | N19: 1 | O19: 0 | AG19: 20.5 | AH19: 30.7 | AI19: 24 | AJ19: 34.3 | AK19: 36.1 | AL19: 23.9 | AM19: 29.9 | AN19: 30.6 | AO19: 20.9 | AP19: 27.5 | AQ19: 25.1 | AR19: 23.1 | AS19: 26.5 | AT19: 26.7 | AU19: 30.8 | AV19: 25.1 | AW19: 33.1 | AX19: 0 | AY19: 0 | AZ19: 0 | BA19: 0 | BB19: 0 | BC19: 0 | BD19: 0 | BE19: 0 | BF19: 0 | BG19: 0 | BH19: 0 | BI19: 0 | BJ19: 0 | BK19: 0 | BL19: 0 | BM19: 0 | BN19: 0 | BO19: =AG19/$AW19 -> 0.61933535 | BP19: =AH19/$AW19 -> 0.92749245 | BQ19: =AI19/$AW19 -> 0.72507553 | BR19: =AJ19/$AW19 -> 1.0362538 | BS19: =AK19/$AW19 -> 1.0906344 | BT19: =AL19/$AW19 -> 0.72205438 | BU19: =AM19/$AW19 -> 0.90332326 | BV19: =AN19/$AW19 -> 0.9244713 | ... CE19: =AW19/$AW19 -> 1 | CF19: =AX19*NF!B$6 -> 0 | CG19: =AY19*NF!C$6 -> 0 | CH19: =AZ19*NF!D$6 -> 0 | CI19: =BA19*NF!E$6 -> 0 | CJ19: =BB19*NF!F$6 -> 0 | CK19: =BC19*NF!G$6 -> 0 | CL19: =BD19*NF!H$6 -> 0 | CM19: =BE19*NF!I$6 -> 0 | ... DM19: =CE19*NF!AI$6 -> 1
A20: Low | B20: Q8NF91 | C20: Nesprin-1 OS=Homo sapiens OX=9606 GN=SYNE1 PE=1 SV=4 | D20: 0.281 | E20: 0.794 | F20: 0 | G20: 1 | H20: 1 | I20: 1 | J20: 8797 | K20: 1010.5 | L20: 5.53 | M20: 0 | N20: 1 | O20: 0 | AG20: 20.8 | AH20: 25.7 | AI20: 14.1 | AJ20: 14.8 | AK20: 17.9 | AL20: 14 | AM20: 16.7 | AN20: 12.9 | AO20: 23.4 | AP20: 15.1 | AQ20: 16.5 | AR20: 22.1 | AS20: 18 | AT20: 23.9 | AU20: 19 | AV20: 11 | AW20: 18 | AX20: 0 | AY20: 0 | AZ20: 0 | BA20: 0 | BB20: 0 | BC20: 0 | BD20: 0 | BE20: 0 | BF20: 0 | BG20: 0 | BH20: 0 | BI20: 0 | BJ20: 0 | BK20: 0 | BL20: 0 | BM20: 0 | BN20: 0 | BO20: =AG20/$AW20 -> 1.1555556 | BP20: =AH20/$AW20 -> 1.4277778 | BQ20: =AI20/$AW20 -> 0.78333333 | BR20: =AJ20/$AW20 -> 0.82222222 | BS20: =AK20/$AW20 -> 0.99444444 | BT20: =AL20/$AW20 -> 0.77777778 | BU20: =AM20/$AW20 -> 0.92777778 | BV20: =AN20/$AW20 -> 0.71666667 | ... CE20: =AW20/$AW20 -> 1 | CF20: =AX20*NF!B$6 -> 0 | CG20: =AY20*NF!C$6 -> 0 | CH20: =AZ20*NF!D$6 -> 0 | CI20: =BA20*NF!E$6 -> 0 | CJ20: =BB20*NF!F$6 -> 0 | CK20: =BC20*NF!G$6 -> 0 | CL20: =BD20*NF!H$6 -> 0 | CM20: =BE20*NF!I$6 -> 0 | ... DM20: =CE20*NF!AI$6 -> 1
A21: Medium | B21: P17174 | C21: Aspartate aminotransferase, cytoplasmic OS=Homo sapiens OX=9606 GN=GOT1 PE=1 SV=3 | D21: 0.025 | E21: 3.003 | F21: 5 | G21: 1 | H21: 1 | I21: 1 | J21: 413 | K21: 46.2 | L21: 7.01 | M21: 2.33 | N21: 1 | O21: 0 | AG21: 21.4 | AH21: 23.7 | AI21: 19 | AJ21: 21.4 | AK21: 24.1 | AL21: 18.7 | AM21: 18.8 | AN21: 20.4 | AO21: 15 | AP21: 17.3 | AQ21: 21.2 | AR21: 15.9 | AS21: 19.8 | AT21: 16.6 | AU21: 16.9 | AV21: 20.9 | AW21: 12 | AX21: 0 | AY21: 0 | AZ21: 0 | BA21: 0 | BB21: 0 | BC21: 0 | BD21: 0 | BE21: 0 | BF21: 0 | BG21: 0 | BH21: 0 | BI21: 0 | BJ21: 0 | BK21: 0 | BL21: 0 | BM21: 0 | BN21: 0 | BO21: =AG21/$AW21 -> 1.7833333 | BP21: =AH21/$AW21 -> 1.975 | BQ21: =AI21/$AW21 -> 1.5833333 | BR21: =AJ21/$AW21 -> 1.7833333 | BS21: =AK21/$AW21 -> 2.0083333 | BT21: =AL21/$AW21 -> 1.5583333 | BU21: =AM21/$AW21 -> 1.5666667 | BV21: =AN21/$AW21 -> 1.7 | ... CE21: =AW21/$AW21 -> 1 | CF21: =AX21*NF!B$6 -> 0 | CG21: =AY21*NF!C$6 -> 0 | CH21: =AZ21*NF!D$6 -> 0 | CI21: =BA21*NF!E$6 -> 0 | CJ21: =BB21*NF!F$6 -> 0 | CK21: =BC21*NF!G$6 -> 0 | CL21: =BD21*NF!H$6 -> 0 | CM21: =BE21*NF!I$6 -> 0 | ... DM21: =CE21*NF!AI$6 -> 1
A22: Low | B22: Q8TBN0 | C22: Guanine nucleotide exchange factor for Rab-3A OS=Homo sapiens OX=9606 GN=RAB3IL1 PE=1 SV=1 | D22: 0.278 | E22: 0.804 | F22: 3 | G22: 1 | H22: 1 | I22: 1 | J22: 382 | K22: 42.6 | L22: 6.47 | M22: 0 | N22: 1 | O22: 0 | AG22: 21.6 | AH22: 24.6 | AI22: 24.2 | AJ22: 32.3 | AK22: 31.8 | AL22: 21.2 | AM22: 20.2 | AN22: 24.2 | AO22: 15.4 | AP22: 20.9 | AQ22: 18.7 | AR22: 16.6 | AS22: 22.2 | AT22: 16.9 | AU22: 16.2 | AV22: 21.8 | AW22: 16.5 | AX22: 0 | AY22: 0 | AZ22: 0 | BA22: 0 | BB22: 0 | BC22: 0 | BD22: 0 | BE22: 0 | BF22: 0 | BG22: 0 | BH22: 0 | BI22: 0 | BJ22: 0 | BK22: 0 | BL22: 0 | BM22: 0 | BN22: 0 | BO22: =AG22/$AW22 -> 1.3090909 | BP22: =AH22/$AW22 -> 1.4909091 | BQ22: =AI22/$AW22 -> 1.4666667 | BR22: =AJ22/$AW22 -> 1.9575758 | BS22: =AK22/$AW22 -> 1.9272727 | BT22: =AL22/$AW22 -> 1.2848485 | BU22: =AM22/$AW22 -> 1.2242424 | BV22: =AN22/$AW22 -> 1.4666667 | ... CE22: =AW22/$AW22 -> 1 | CF22: =AX22*NF!B$6 -> 0 | CG22: =AY22*NF!C$6 -> 0 | CH22: =AZ22*NF!D$6 -> 0 | CI22: =BA22*NF!E$6 -> 0 | CJ22: =BB22*NF!F$6 -> 0 | CK22: =BC22*NF!G$6 -> 0 | CL22: =BD22*NF!H$6 -> 0 | CM22: =BE22*NF!I$6 -> 0 | ... DM22: =CE22*NF!AI$6 -> 1
A23: Low | B23: Q9C0E2 | C23: Exportin-4 OS=Homo sapiens OX=9606 GN=XPO4 PE=1 SV=2 | D23: 0.184 | E23: 1.168 | F23: 1 | G23: 1 | H23: 1 | I23: 1 | J23: 1151 | K23: 130.1 | L23: 5.05 | M23: 0 | N23: 1 | O23: 0 | AG23: 21.7 | AH23: 15.7 | AI23: 17.1 | AJ23: 23.2 | AK23: 19.7 | AL23: 21 | AM23: 21.9 | AN23: 16 | AO23: 15.7 | AP23: 18.1 | AQ23: 14.4 | AR23: 14.5 | AS23: 14.6 | AT23: 13.9 | AU23: 12.3 | AV23: 14.5 | AW23: 12.2 | AX23: 0 | AY23: 0 | AZ23: 0 | BA23: 0 | BB23: 0 | BC23: 0 | BD23: 0 | BE23: 0 | BF23: 0 | BG23: 0 | BH23: 0 | BI23: 0 | BJ23: 0 | BK23: 0 | BL23: 0 | BM23: 0 | BN23: 0 | BO23: =AG23/$AW23 -> 1.7786885 | BP23: =AH23/$AW23 -> 1.2868852 | BQ23: =AI23/$AW23 -> 1.4016393 | BR23: =AJ23/$AW23 -> 1.9016393 | BS23: =AK23/$AW23 -> 1.6147541 | BT23: =AL23/$AW23 -> 1.7213115 | BU23: =AM23/$AW23 -> 1.795082 | BV23: =AN23/$AW23 -> 1.3114754 | ... CE23: =AW23/$AW23 -> 1 | CF23: =AX23*NF!B$6 -> 0 | CG23: =AY23*NF!C$6 -> 0 | CH23: =AZ23*NF!D$6 -> 0 | CI23: =BA23*NF!E$6 -> 0 | CJ23: =BB23*NF!F$6 -> 0 | CK23: =BC23*NF!G$6 -> 0 | CL23: =BD23*NF!H$6 -> 0 | CM23: =BE23*NF!I$6 -> 0 | ... DM23: =CE23*NF!AI$6 -> 1
A24: Low | B24: Q9UK05 | C24: Growth/differentiation factor 2 OS=Homo sapiens OX=9606 GN=GDF2 PE=1 SV=1 | D24: 0.172 | E24: 1.214 | F24: 2 | G24: 1 | H24: 1 | I24: 1 | J24: 429 | K24: 47.3 | L24: 6.48 | M24: 0 | N24: 1 | O24: 0 | AG24: 21.7 | AH24: 21.2 | AI24: 27.4 | AJ24: 23.2 | AK24: 31.6 | AL24: 32.7 | AM24: 33 | AN24: 28.5 | AO24: 25.7 | AP24: 38.6 | AQ24: 31.7 | AR24: 26.4 | AS24: 32.4 | AT24: 22.2 | AU24: 27.8 | AV24: 27.4 | AW24: 24.5 | AX24: 0 | AY24: 0 | AZ24: 0 | BA24: 0 | BB24: 0 | BC24: 0 | BD24: 0 | BE24: 0 | BF24: 0 | BG24: 0 | BH24: 0 | BI24: 0 | BJ24: 0 | BK24: 0 | BL24: 0 | BM24: 0 | BN24: 0 | BO24: =AG24/$AW24 -> 0.88571429 | BP24: =AH24/$AW24 -> 0.86530612 | BQ24: =AI24/$AW24 -> 1.1183673 | BR24: =AJ24/$AW24 -> 0.94693878 | BS24: =AK24/$AW24 -> 1.2897959 | BT24: =AL24/$AW24 -> 1.3346939 | BU24: =AM24/$AW24 -> 1.3469388 | BV24: =AN24/$AW24 -> 1.1632653 | ... CE24: =AW24/$AW24 -> 1 | CF24: =AX24*NF!B$6 -> 0 | CG24: =AY24*NF!C$6 -> 0 | CH24: =AZ24*NF!D$6 -> 0 | CI24: =BA24*NF!E$6 -> 0 | CJ24: =BB24*NF!F$6 -> 0 | CK24: =BC24*NF!G$6 -> 0 | CL24: =BD24*NF!H$6 -> 0 | CM24: =BE24*NF!I$6 -> 0 | ... DM24: =CE24*NF!AI$6 -> 1
A25: Low | B25: Q9NYZ4 | C25: Sialic acid-binding Ig-like lectin 8 OS=Homo sapiens OX=9606 GN=SIGLEC8 PE=1 SV=2 | D25: 0.267 | E25: 0.834 | F25: 3 | G25: 1 | H25: 2 | I25: 1 | J25: 499 | K25: 54 | L25: 8.09 | M25: 0 | N25: 1 | O25: 0 | P25: 10.3 | Q25: 11.8 | R25: 8.8 | S25: 7.5 | T25: 8.2 | U25: 9.3 | V25: 12.5 | W25: 12.9 | X25: 12.5 | Y25: 11.8 | Z25: 11.7 | AA25: 10.3 | AB25: 9.2 | AC25: 10.9 | AD25: 9.6 | AE25: 8.3 | AF25: 11.7 | AG25: 22.1 | AH25: 16 | AI25: 18.6 | AJ25: 23.4 | AK25: 31.5 | AL25: 20.2 | AM25: 42.3 | AN25: 19.4 | AO25: 22.2 | AP25: 29.7 | AQ25: 18.9 | AR25: 19.6 | AS25: 18.8 | AT25: 16.4 | AU25: 14.5 | AV25: 18.9 | AW25: 24.8 | AX25: =P25/$AF25 -> 0.88034188 | AY25: =Q25/$AF25 -> 1.008547 | AZ25: =R25/$AF25 -> 0.75213675 | BA25: =S25/$AF25 -> 0.64102564 | BB25: =T25/$AF25 -> 0.7008547 | BC25: =U25/$AF25 -> 0.79487179 | BD25: =V25/$AF25 -> 1.0683761 | BE25: =W25/$AF25 -> 1.1025641 | ... BN25: =AF25/$AF25 -> 1 | BO25: =AG25/$AW25 -> 0.89112903 | BP25: =AH25/$AW25 -> 0.64516129 | BQ25: =AI25/$AW25 -> 0.75 | BR25: =AJ25/$AW25 -> 0.94354839 | BS25: =AK25/$AW25 -> 1.2701613 | BT25: =AL25/$AW25 -> 0.81451613 | BU25: =AM25/$AW25 -> 1.7056452 | BV25: =AN25/$AW25 -> 0.78225806 | ... CE25: =AW25/$AW25 -> 1 | CF25: =AX25*NF!B$6 -> 0.90113737 | CG25: =AY25*NF!C$6 -> 0.90692865 | CH25: =AZ25*NF!D$6 -> 0.68273357 | CI25: =BA25*NF!E$6 -> 0.53321816 | CJ25: =BB25*NF!F$6 -> 0.56387865 | CK25: =BC25*NF!G$6 -> 0.59052337 | CL25: =BD25*NF!H$6 -> 0.77361151 | CM25: =BE25*NF!I$6 -> 0.89481918 | ... DM25: =CE25*NF!AI$6 -> 1
A26: Low | B26: P98164 | C26: Low-density lipoprotein receptor-related protein 2 OS=Homo sapiens OX=9606 GN=LRP2 PE=1 SV=3 | D26: 0.264 | E26: 0.859 | F26: 0 | G26: 1 | H26: 1 | I26: 1 | J26: 4655 | K26: 521.6 | L26: 5.08 | M26: 0 | N26: 1 | O26: 0 | AG26: 22.6 | AH26: 28.4 | AI26: 14.6 | AJ26: 23.6 | AK26: 29 | AL26: 20.2 | AM26: 26.4 | AN26: 22.2 | AO26: 21.3 | AP26: 22 | AQ26: 17.5 | AR26: 11.4 | AS26: 18.2 | AT26: 20 | AU26: 26.4 | AV26: 17 | AW26: 24 | AX26: 0 | AY26: 0 | AZ26: 0 | BA26: 0 | BB26: 0 | BC26: 0 | BD26: 0 | BE26: 0 | BF26: 0 | BG26: 0 | BH26: 0 | BI26: 0 | BJ26: 0 | BK26: 0 | BL26: 0 | BM26: 0 | BN26: 0 | BO26: =AG26/$AW26 -> 0.94166667 | BP26: =AH26/$AW26 -> 1.1833333 | BQ26: =AI26/$AW26 -> 0.60833333 | BR26: =AJ26/$AW26 -> 0.98333333 | BS26: =AK26/$AW26 -> 1.2083333 | BT26: =AL26/$AW26 -> 0.84166667 | BU26: =AM26/$AW26 -> 1.1 | BV26: =AN26/$AW26 -> 0.925 | ... CE26: =AW26/$AW26 -> 1 | CF26: =AX26*NF!B$6 -> 0 | CG26: =AY26*NF!C$6 -> 0 | CH26: =AZ26*NF!D$6 -> 0 | CI26: =BA26*NF!E$6 -> 0 | CJ26: =BB26*NF!F$6 -> 0 | CK26: =BC26*NF!G$6 -> 0 | CL26: =BD26*NF!H$6 -> 0 | CM26: =BE26*NF!I$6 -> 0 | ... DM26: =CE26*NF!AI$6 -> 1
A27: Medium | B27: A0A0C4DH38 | C27: Immunoglobulin heavy variable 5-51 OS=Homo sapiens OX=9606 GN=IGHV5-51 PE=3 SV=1 | D27: 0.011 | E27: 4.036 | F27: 14 | G27: 1 | H27: 1 | I27: 1 | J27: 117 | K27: 12.7 | L27: 8.27 | M27: 2.47 | N27: 1 | O27: 0 | AG27: 22.9 | AH27: 28.7 | AI27: 25.9 | AJ27: 29.2 | AK27: 30.3 | AL27: 29.9 | AM27: 35.9 | AN27: 22.7 | AO27: 22.6 | AP27: 21.8 | AQ27: 18.4 | AR27: 21.5 | AS27: 20.8 | AT27: 22.6 | AU27: 19.7 | AV27: 27.1 | AW27: 26.7 | AX27: 0 | AY27: 0 | AZ27: 0 | BA27: 0 | BB27: 0 | BC27: 0 | BD27: 0 | BE27: 0 | BF27: 0 | BG27: 0 | BH27: 0 | BI27: 0 | BJ27: 0 | BK27: 0 | BL27: 0 | BM27: 0 | BN27: 0 | BO27: =AG27/$AW27 -> 0.8576779 | BP27: =AH27/$AW27 -> 1.0749064 | BQ27: =AI27/$AW27 -> 0.97003745 | BR27: =AJ27/$AW27 -> 1.093633 | BS27: =AK27/$AW27 -> 1.1348315 | BT27: =AL27/$AW27 -> 1.1198502 | BU27: =AM27/$AW27 -> 1.3445693 | BV27: =AN27/$AW27 -> 0.85018727 | ... CE27: =AW27/$AW27 -> 1 | CF27: =AX27*NF!B$6 -> 0 | CG27: =AY27*NF!C$6 -> 0 | CH27: =AZ27*NF!D$6 -> 0 | CI27: =BA27*NF!E$6 -> 0 | CJ27: =BB27*NF!F$6 -> 0 | CK27: =BC27*NF!G$6 -> 0 | CL27: =BD27*NF!H$6 -> 0 | CM27: =BE27*NF!I$6 -> 0 | ... DM27: =CE27*NF!AI$6 -> 1
A28: Medium | B28: Q15262 | C28: Receptor-type tyrosine-protein phosphatase kappa OS=Homo sapiens OX=9606 GN=PTPRK PE=1 SV=2 | D28: 0.018 | E28: 3.506 | F28: 1 | G28: 1 | H28: 1 | I28: 1 | J28: 1439 | K28: 162 | L28: 5.9 | M28: 2.45 | N28: 1 | O28: 0 | AG28: 23.3 | AH28: 27.5 | AI28: 21.6 | AJ28: 24.3 | AK28: 28.5 | AL28: 19.1 | AM28: 27.6 | AN28: 22.6 | AO28: 16.9 | AP28: 27.7 | AQ28: 20.1 | AR28: 18.1 | AS28: 19.3 | AT28: 18.3 | AU28: 17.7 | AV28: 16 | AW28: 25.7 | AX28: 0 | AY28: 0 | AZ28: 0 | BA28: 0 | BB28: 0 | BC28: 0 | BD28: 0 | BE28: 0 | BF28: 0 | BG28: 0 | BH28: 0 | BI28: 0 | BJ28: 0 | BK28: 0 | BL28: 0 | BM28: 0 | BN28: 0 | BO28: =AG28/$AW28 -> 0.90661479 | BP28: =AH28/$AW28 -> 1.0700389 | BQ28: =AI28/$AW28 -> 0.84046693 | BR28: =AJ28/$AW28 -> 0.94552529 | BS28: =AK28/$AW28 -> 1.1089494 | BT28: =AL28/$AW28 -> 0.74319066 | BU28: =AM28/$AW28 -> 1.07393 | BV28: =AN28/$AW28 -> 0.87937743 | ... CE28: =AW28/$AW28 -> 1 | CF28: =AX28*NF!B$6 -> 0 | CG28: =AY28*NF!C$6 -> 0 | CH28: =AZ28*NF!D$6 -> 0 | CI28: =BA28*NF!E$6 -> 0 | CJ28: =BB28*NF!F$6 -> 0 | CK28: =BC28*NF!G$6 -> 0 | CL28: =BD28*NF!H$6 -> 0 | CM28: =BE28*NF!I$6 -> 0 | ... DM28: =CE28*NF!AI$6 -> 1
A29: Low | B29: Q9NYT6 | C29: Zinc finger protein 226 OS=Homo sapiens OX=9606 GN=ZNF226 PE=2 SV=2 | D29: 0.283 | E29: 0.789 | F29: 2 | G29: 1 | H29: 1 | I29: 1 | J29: 803 | K29: 91.9 | L29: 8.7 | M29: 0 | N29: 1 | O29: 0 | AG29: 23.8 | AH29: 22.6 | AI29: 24.1 | AJ29: 25.9 | AK29: 26.2 | AL29: 27.1 | AM29: 32.8 | AN29: 28.7 | AO29: 23.4 | AP29: 23.6 | AQ29: 24.8 | AR29: 25.9 | AS29: 20.9 | AT29: 22.9 | AU29: 26 | AV29: 25.9 | AW29: 19 | AX29: 0 | AY29: 0 | AZ29: 0 | BA29: 0 | BB29: 0 | BC29: 0 | BD29: 0 | BE29: 0 | BF29: 0 | BG29: 0 | BH29: 0 | BI29: 0 | BJ29: 0 | BK29: 0 | BL29: 0 | BM29: 0 | BN29: 0 | BO29: =AG29/$AW29 -> 1.2526316 | BP29: =AH29/$AW29 -> 1.1894737 | BQ29: =AI29/$AW29 -> 1.2684211 | BR29: =AJ29/$AW29 -> 1.3631579 | BS29: =AK29/$AW29 -> 1.3789474 | BT29: =AL29/$AW29 -> 1.4263158 | BU29: =AM29/$AW29 -> 1.7263158 | BV29: =AN29/$AW29 -> 1.5105263 | ... CE29: =AW29/$AW29 -> 1 | CF29: =AX29*NF!B$6 -> 0 | CG29: =AY29*NF!C$6 -> 0 | CH29: =AZ29*NF!D$6 -> 0 | CI29: =BA29*NF!E$6 -> 0 | CJ29: =BB29*NF!F$6 -> 0 | CK29: =BC29*NF!G$6 -> 0 | CL29: =BD29*NF!H$6 -> 0 | CM29: =BE29*NF!I$6 -> 0 | ... DM29: =CE29*NF!AI$6 -> 1
A30: Low | B30: Q6P1M3 | C30: LLGL scribble cell polarity complex component 2 OS=Homo sapiens OX=9606 GN=LLGL2 PE=1 SV=2 | D30: 0.26 | E30: 0.871 | F30: 1 | G30: 1 | H30: 1 | I30: 1 | J30: 1020 | K30: 113.4 | L30: 7.52 | M30: 0 | N30: 1 | O30: 0 | AG30: 24.4 | AH30: 35.9 | AI30: 26 | AJ30: 47.4 | AK30: 37 | AL30: 28.2 | AM30: 31.8 | AN30: 34.7 | AO30: 31.9 | AP30: 32 | AQ30: 30.2 | AR30: 31.5 | AS30: 25.8 | AT30: 30.4 | AU30: 32.4 | AV30: 34.3 | AW30: 30.1 | AX30: 0 | AY30: 0 | AZ30: 0 | BA30: 0 | BB30: 0 | BC30: 0 | BD30: 0 | BE30: 0 | BF30: 0 | BG30: 0 | BH30: 0 | BI30: 0 | BJ30: 0 | BK30: 0 | BL30: 0 | BM30: 0 | BN30: 0 | BO30: =AG30/$AW30 -> 0.81063123 | BP30: =AH30/$AW30 -> 1.192691 | BQ30: =AI30/$AW30 -> 0.86378738 | BR30: =AJ30/$AW30 -> 1.5747508 | BS30: =AK30/$AW30 -> 1.2292359 | BT30: =AL30/$AW30 -> 0.93687708 | BU30: =AM30/$AW30 -> 1.0564784 | BV30: =AN30/$AW30 -> 1.1528239 | ... CE30: =AW30/$AW30 -> 1 | CF30: =AX30*NF!B$6 -> 0 | CG30: =AY30*NF!C$6 -> 0 | CH30: =AZ30*NF!D$6 -> 0 | CI30: =BA30*NF!E$6 -> 0 | CJ30: =BB30*NF!F$6 -> 0 | CK30: =BC30*NF!G$6 -> 0 | CL30: =BD30*NF!H$6 -> 0 | CM30: =BE30*NF!I$6 -> 0 | ... DM30: =CE30*NF!AI$6 -> 1
A31: Low | B31: Q13873 | C31: Bone morphogenetic protein receptor type-2 OS=Homo sapiens OX=9606 GN=BMPR2 PE=1 SV=2 | D31: 0.134 | E31: 1.463 | F31: 1 | G31: 1 | H31: 1 | I31: 1 | J31: 1038 | K31: 115.1 | L31: 6.2 | M31: 0 | N31: 1 | O31: 0 | AG31: 24.5 | AH31: 109.5 | AI31: 14.1 | AJ31: 89.6 | AK31: 38.2 | AL31: 80.4 | AM31: 61.3 | AN31: 23 | AO31: 26 | AP31: 55.9 | AQ31: 13.7 | AR31: 21 | AS31: 12.8 | AT31: 29.1 | AU31: 14.6 | AV31: 30.8 | AW31: 20.7 | AX31: 0 | AY31: 0 | AZ31: 0 | BA31: 0 | BB31: 0 | BC31: 0 | BD31: 0 | BE31: 0 | BF31: 0 | BG31: 0 | BH31: 0 | BI31: 0 | BJ31: 0 | BK31: 0 | BL31: 0 | BM31: 0 | BN31: 0 | BO31: =AG31/$AW31 -> 1.1835749 | BP31: =AH31/$AW31 -> 5.2898551 | BQ31: =AI31/$AW31 -> 0.68115942 | BR31: =AJ31/$AW31 -> 4.3285024 | BS31: =AK31/$AW31 -> 1.8454106 | BT31: =AL31/$AW31 -> 3.884058 | BU31: =AM31/$AW31 -> 2.9613527 | BV31: =AN31/$AW31 -> 1.1111111 | ... CE31: =AW31/$AW31 -> 1 | CF31: =AX31*NF!B$6 -> 0 | CG31: =AY31*NF!C$6 -> 0 | CH31: =AZ31*NF!D$6 -> 0 | CI31: =BA31*NF!E$6 -> 0 | CJ31: =BB31*NF!F$6 -> 0 | CK31: =BC31*NF!G$6 -> 0 | CL31: =BD31*NF!H$6 -> 0 | CM31: =BE31*NF!I$6 -> 0 | ... DM31: =CE31*NF!AI$6 -> 1
A32: Low | B32: O60879 | C32: Protein diaphanous homolog 2 OS=Homo sapiens OX=9606 GN=DIAPH2 PE=1 SV=1 | D32: 0.287 | E32: 0.769 | F32: 1 | G32: 1 | H32: 1 | I32: 1 | J32: 1101 | K32: 125.5 | L32: 6.58 | M32: 0 | N32: 1 | O32: 0 | AG32: 24.5 | AH32: 30.8 | AI32: 38.6 | AJ32: 51.2 | AK32: 77.4 | AL32: 31.2 | AM32: 51.5 | AN32: 26.5 | AO32: 22.1 | AP32: 41.3 | AQ32: 40.4 | AR32: 29.9 | AS32: 31.9 | AT32: 18.6 | AU32: 37.4 | AV32: 37.3 | AW32: 27 | AX32: 0 | AY32: 0 | AZ32: 0 | BA32: 0 | BB32: 0 | BC32: 0 | BD32: 0 | BE32: 0 | BF32: 0 | BG32: 0 | BH32: 0 | BI32: 0 | BJ32: 0 | BK32: 0 | BL32: 0 | BM32: 0 | BN32: 0 | BO32: =AG32/$AW32 -> 0.90740741 | BP32: =AH32/$AW32 -> 1.1407407 | BQ32: =AI32/$AW32 -> 1.4296296 | BR32: =AJ32/$AW32 -> 1.8962963 | BS32: =AK32/$AW32 -> 2.8666667 | BT32: =AL32/$AW32 -> 1.1555556 | BU32: =AM32/$AW32 -> 1.9074074 | BV32: =AN32/$AW32 -> 0.98148148 | ... CE32: =AW32/$AW32 -> 1 | CF32: =AX32*NF!B$6 -> 0 | CG32: =AY32*NF!C$6 -> 0 | CH32: =AZ32*NF!D$6 -> 0 | CI32: =BA32*NF!E$6 -> 0 | CJ32: =BB32*NF!F$6 -> 0 | CK32: =BC32*NF!G$6 -> 0 | CL32: =BD32*NF!H$6 -> 0 | CM32: =BE32*NF!I$6 -> 0 | ... DM32: =CE32*NF!AI$6 -> 1
A33: Medium | B33: Q99674 | C33: Cell growth regulator with EF hand domain protein 1 OS=Homo sapiens OX=9606 GN=CGREF1 PE=2 SV=3 | D33: 0.024 | E33: 3.061 | F33: 3 | G33: 1 | H33: 3 | I33: 1 | J33: 318 | K33: 33.4 | L33: 4.39 | M33: 4.74 | N33: 1 | O33: 0 | P33: 23.8 | Q33: 34.3 | R33: 41.5 | S33: 33.2 | T33: 33.3 | U33: 53.8 | V33: 87 | W33: 32.3 | X33: 39.9 | Y33: 20.9 | Z33: 26.7 | AA33: 31.9 | AB33: 22.5 | AC33: 28.1 | AD33: 53 | AE33: 35.1 | AF33: 53.8 | AG33: 24.6 | AH33: 47 | AI33: 42.4 | AJ33: 45.1 | AK33: 34.9 | AL33: 33.2 | AM33: 30.2 | AN33: 22.6 | AO33: 26.5 | AP33: 60 | AQ33: 18.9 | AR33: 25.5 | AS33: 27.7 | AT33: 24.8 | AU33: 35.7 | AV33: 36.9 | AW33: 32.2 | AX33: =P33/$AF33 -> 0.44237918 | AY33: =Q33/$AF33 -> 0.63754647 | AZ33: =R33/$AF33 -> 0.77137546 | BA33: =S33/$AF33 -> 0.61710037 | BB33: =T33/$AF33 -> 0.61895911 | BC33: =U33/$AF33 -> 1 | BD33: =V33/$AF33 -> 1.6171004 | BE33: =W33/$AF33 -> 0.60037175 | ... BN33: =AF33/$AF33 -> 1 | BO33: =AG33/$AW33 -> 0.76397516 | BP33: =AH33/$AW33 -> 1.4596273 | BQ33: =AI33/$AW33 -> 1.3167702 | BR33: =AJ33/$AW33 -> 1.4006211 | BS33: =AK33/$AW33 -> 1.0838509 | BT33: =AL33/$AW33 -> 1.0310559 | BU33: =AM33/$AW33 -> 0.9378882 | BV33: =AN33/$AW33 -> 0.70186335 | ... CE33: =AW33/$AW33 -> 1 | CF33: =AX33*NF!B$6 -> 0.45282909 | CG33: =AY33*NF!C$6 -> 0.57330908 | CH33: =AZ33*NF!D$6 -> 0.70019704 | CI33: =BA33*NF!E$6 -> 0.51331664 | CJ33: =BB33*NF!F$6 -> 0.49798885 | CK33: =BC33*NF!G$6 -> 0.7429165 | CL33: =BD33*NF!H$6 -> 1.170943 | CM33: =BE33*NF!I$6 -> 0.48724981 | ... DM33: =CE33*NF!AI$6 -> 1
A34: High | B34: P14923 | C34: Junction plakoglobin OS=Homo sapiens OX=9606 GN=JUP PE=1 SV=3 | D34: 0 | E34: 9.77 | F34: 4 | G34: 3 | H34: 6 | I34: 3 | J34: 745 | K34: 81.7 | L34: 6.14 | M34: 10.52 | N34: 3 | O34: 0 | P34: 139.6 | Q34: 177.8 | R34: 168.1 | S34: 132.1 | T34: 252.1 | U34: 126.9 | V34: 143.5 | W34: 134.7 | X34: 271.4 | Y34: 130.4 | Z34: 148.9 | AA34: 129.2 | AB34: 234.9 | AC34: 264.6 | AD34: 228.2 | AE34: 181 | AF34: 226.1 | AG34: 24.8 | AH34: 33.9 | AI34: 31.5 | AJ34: 66.1 | AK34: 139.8 | AL34: 21.1 | AM34: 46.9 | AN34: 62.4 | AO34: 41.1 | AP34: 20.1 | AQ34: 12 | AR34: 22 | AS34: 14 | AT34: 22 | AU34: 28.5 | AV34: 28.8 | AW34: 14.4 | AX34: =P34/$AF34 -> 0.61742592 | AY34: =Q34/$AF34 -> 0.78637771 | AZ34: =R34/$AF34 -> 0.74347634 | BA34: =S34/$AF34 -> 0.58425475 | BB34: =T34/$AF34 -> 1.1149934 | BC34: =U34/$AF34 -> 0.56125608 | BD34: =V34/$AF34 -> 0.63467492 | BE34: =W34/$AF34 -> 0.59575409 | ... BN34: =AF34/$AF34 -> 1 | BO34: =AG34/$AW34 -> 1.7222222 | BP34: =AH34/$AW34 -> 2.3541667 | BQ34: =AI34/$AW34 -> 2.1875 | BR34: =AJ34/$AW34 -> 4.5902778 | BS34: =AK34/$AW34 -> 9.7083333 | BT34: =AL34/$AW34 -> 1.4652778 | BU34: =AM34/$AW34 -> 3.2569444 | BV34: =AN34/$AW34 -> 4.3333333 | ... CE34: =AW34/$AW34 -> 1 | CF34: =AX34*NF!B$6 -> 0.63201079 | CG34: =AY34*NF!C$6 -> 0.7071445 | CH34: =AZ34*NF!D$6 -> 0.67487229 | CI34: =BA34*NF!E$6 -> 0.48599498 | CJ34: =BB34*NF!F$6 -> 0.89707745 | CK34: =BC34*NF!G$6 -> 0.4169664 | CL34: =BD34*NF!H$6 -> 0.45956835 | CM34: =BE34*NF!I$6 -> 0.48350222 | ... DM34: =CE34*NF!AI$6 -> 1
A35: High | B35: P52209 | C35: 6-phosphogluconate dehydrogenase, decarboxylating OS=Homo sapiens OX=9606 GN=PGD PE=1 SV=3 | D35: 0.008 | E35: 4.294 | F35: 6 | G35: 2 | H35: 2 | I35: 2 | J35: 483 | K35: 53.1 | L35: 7.23 | M35: 2.42 | N35: 2 | O35: 0 | P35: 10.5 | Q35: 22.6 | R35: 23.3 | S35: 17.6 | T35: 19.7 | U35: 20 | V35: 24.9 | W35: 28 | X35: 27.5 | Y35: 29.8 | Z35: 33.4 | AA35: 21.5 | AB35: 21.7 | AC35: 30.7 | AD35: 17.2 | AE35: 20.5 | AF35: 19.9 | AG35: 25.1 | AH35: 24.9 | AI35: 26.3 | AJ35: 24.9 | AK35: 30.1 | AL35: 30 | AM35: 36.1 | AN35: 30.8 | AO35: 21.1 | AP35: 35.2 | AQ35: 29.4 | AR35: 27.6 | AS35: 23.9 | AT35: 28.7 | AU35: 27.6 | AV35: 26.4 | AW35: 22.2 | AX35: =P35/$AF35 -> 0.52763819 | AY35: =Q35/$AF35 -> 1.1356784 | AZ35: =R35/$AF35 -> 1.1708543 | BA35: =S35/$AF35 -> 0.88442211 | BB35: =T35/$AF35 -> 0.98994975 | BC35: =U35/$AF35 -> 1.0050251 | BD35: =V35/$AF35 -> 1.2512563 | BE35: =W35/$AF35 -> 1.4070352 | ... BN35: =AF35/$AF35 -> 1 | BO35: =AG35/$AW35 -> 1.1306306 | BP35: =AH35/$AW35 -> 1.1216216 | BQ35: =AI35/$AW35 -> 1.1846847 | BR35: =AJ35/$AW35 -> 1.1216216 | BS35: =AK35/$AW35 -> 1.3558559 | BT35: =AL35/$AW35 -> 1.3513514 | BU35: =AM35/$AW35 -> 1.6261261 | BV35: =AN35/$AW35 -> 1.3873874 | ... CE35: =AW35/$AW35 -> 1 | CF35: =AX35*NF!B$6 -> 0.54010209 | CG35: =AY35*NF!C$6 -> 1.0212506 | CH35: =AZ35*NF!D$6 -> 1.0628141 | CI35: =BA35*NF!E$6 -> 0.73568029 | CJ35: =BB35*NF!F$6 -> 0.79647254 | CK35: =BC35*NF!G$6 -> 0.74664974 | CL35: =BD35*NF!H$6 -> 0.90603514 | CM35: =BE35*NF!I$6 -> 1.1419219 | ... DM35: =CE35*NF!AI$6 -> 1
A36: Low | B36: O00519 | C36: Fatty-acid amide hydrolase 1 OS=Homo sapiens OX=9606 GN=FAAH PE=1 SV=2 | D36: 0.257 | E36: 0.876 | F36: 2 | G36: 1 | H36: 4 | I36: 1 | J36: 579 | K36: 63 | L36: 7.66 | M36: 0 | N36: 1 | O36: 0 | P36: 18.4 | Q36: 24.6 | R36: 36.1 | S36: 32.4 | T36: 24.7 | U36: 23.3 | V36: 26.8 | W36: 15.7 | X36: 48.6 | Y36: 23.1 | Z36: 44.4 | AA36: 14 | AB36: 24.2 | AC36: 20.3 | AD36: 16.1 | AE36: 28.8 | AF36: 27.2 | AG36: 25.6 | AH36: 48.7 | AI36: 40.9 | AJ36: 86.6 | AK36: 88.7 | AL36: 43.7 | AM36: 74.2 | AN36: 37.4 | AO36: 37.1 | AP36: 50.4 | AQ36: 32.3 | AR36: 26.1 | AS36: 40 | AT36: 35.7 | AU36: 49 | AV36: 56.4 | AW36: 49.2 | AX36: =P36/$AF36 -> 0.67647059 | AY36: =Q36/$AF36 -> 0.90441176 | AZ36: =R36/$AF36 -> 1.3272059 | BA36: =S36/$AF36 -> 1.1911765 | BB36: =T36/$AF36 -> 0.90808824 | BC36: =U36/$AF36 -> 0.85661765 | BD36: =V36/$AF36 -> 0.98529412 | BE36: =W36/$AF36 -> 0.57720588 | ... BN36: =AF36/$AF36 -> 1 | BO36: =AG36/$AW36 -> 0.5203252 | BP36: =AH36/$AW36 -> 0.9898374 | BQ36: =AI36/$AW36 -> 0.83130081 | BR36: =AJ36/$AW36 -> 1.7601626 | BS36: =AK36/$AW36 -> 1.8028455 | BT36: =AL36/$AW36 -> 0.88821138 | BU36: =AM36/$AW36 -> 1.5081301 | BV36: =AN36/$AW36 -> 0.7601626 | ... CE36: =AW36/$AW36 -> 1 | CF36: =AX36*NF!B$6 -> 0.69245022 | CG36: =AY36*NF!C$6 -> 0.81328578 | CH36: =AZ36*NF!D$6 -> 1.2047384 | CI36: =BA36*NF!E$6 -> 0.99084481 | CJ36: =BB36*NF!F$6 -> 0.73061016 | CK36: =BC36*NF!G$6 -> 0.63639538 | CL36: =BD36*NF!H$6 -> 0.71345184 | CM36: =BE36*NF!I$6 -> 0.46844886 | ... DM36: =CE36*NF!AI$6 -> 1
A37: Low | B37: Q92626 | C37: Peroxidasin homolog OS=Homo sapiens OX=9606 GN=PXDN PE=1 SV=2 | D37: 0.135 | E37: 1.45 | F37: 1 | G37: 1 | H37: 3 | I37: 1 | J37: 1479 | K37: 165.2 | L37: 7.17 | M37: 0 | N37: 1 | O37: 0 | P37: 22.6 | Q37: 21.2 | R37: 23.1 | S37: 40.5 | T37: 26 | U37: 33.6 | V37: 39.7 | W37: 26.1 | X37: 32.7 | Y37: 21.4 | Z37: 58.2 | AA37: 25.9 | AB37: 24 | AC37: 21.7 | AD37: 19 | AE37: 27.6 | AF37: 23.4 | AG37: 25.9 | AH37: 40 | AI37: 20 | AJ37: 40.8 | AK37: 65.2 | AL37: 27.3 | AM37: 39.6 | AN37: 30.5 | AO37: 30.4 | AP37: 29.9 | AQ37: 27.7 | AR37: 20.7 | AS37: 26.2 | AT37: 21.6 | AU37: 21.9 | AV37: 29.5 | AW37: 28 | AX37: =P37/$AF37 -> 0.96581197 | AY37: =Q37/$AF37 -> 0.90598291 | AZ37: =R37/$AF37 -> 0.98717949 | BA37: =S37/$AF37 -> 1.7307692 | BB37: =T37/$AF37 -> 1.1111111 | BC37: =U37/$AF37 -> 1.4358974 | BD37: =V37/$AF37 -> 1.6965812 | BE37: =W37/$AF37 -> 1.1153846 | ... BN37: =AF37/$AF37 -> 1 | BO37: =AG37/$AW37 -> 0.925 | BP37: =AH37/$AW37 -> 1.4285714 | BQ37: =AI37/$AW37 -> 0.71428571 | BR37: =AJ37/$AW37 -> 1.4571429 | BS37: =AK37/$AW37 -> 2.3285714 | BT37: =AL37/$AW37 -> 0.975 | BU37: =AM37/$AW37 -> 1.4142857 | BV37: =AN37/$AW37 -> 1.0892857 | ... CE37: =AW37/$AW37 -> 1 | CF37: =AX37*NF!B$6 -> 0.98862643 | CG37: =AY37*NF!C$6 -> 0.81469862 | CH37: =AZ37*NF!D$6 -> 0.89608781 | CI37: =BA37*NF!E$6 -> 1.439689 | CJ37: =BB37*NF!F$6 -> 0.89395395 | CK37: =BC37*NF!G$6 -> 1.0667519 | CL37: =BD37*NF!H$6 -> 1.2284951 | CM37: =BE37*NF!I$6 -> 0.90522405 | ... DM37: =CE37*NF!AI$6 -> 1
A38: Low | B38: Q86TZ1 | C38: Tetratricopeptide repeat protein 6 OS=Homo sapiens OX=9606 GN=TTC6 PE=2 SV=1 | D38: 0.253 | E38: 0.885 | F38: 2 | G38: 1 | H38: 1 | I38: 1 | J38: 520 | K38: 59.3 | L38: 6.37 | M38: 0 | N38: 1 | O38: 0 | AG38: 25.9 | AH38: 26.8 | AI38: 24.2 | AJ38: 16 | AK38: 11.7 | AL38: 34.4 | AM38: 17.1 | AN38: 19.2 | AO38: 17.1 | AP38: 19 | AQ38: 19.1 | AR38: 20.8 | AS38: 16.6 | AT38: 24.1 | AU38: 19.5 | AV38: 21.4 | AW38: 14.7 | AX38: 0 | AY38: 0 | AZ38: 0 | BA38: 0 | BB38: 0 | BC38: 0 | BD38: 0 | BE38: 0 | BF38: 0 | BG38: 0 | BH38: 0 | BI38: 0 | BJ38: 0 | BK38: 0 | BL38: 0 | BM38: 0 | BN38: 0 | BO38: =AG38/$AW38 -> 1.7619048 | BP38: =AH38/$AW38 -> 1.8231293 | BQ38: =AI38/$AW38 -> 1.6462585 | BR38: =AJ38/$AW38 -> 1.0884354 | BS38: =AK38/$AW38 -> 0.79591837 | BT38: =AL38/$AW38 -> 2.3401361 | BU38: =AM38/$AW38 -> 1.1632653 | BV38: =AN38/$AW38 -> 1.3061224 | ... CE38: =AW38/$AW38 -> 1 | CF38: =AX38*NF!B$6 -> 0 | CG38: =AY38*NF!C$6 -> 0 | CH38: =AZ38*NF!D$6 -> 0 | CI38: =BA38*NF!E$6 -> 0 | CJ38: =BB38*NF!F$6 -> 0 | CK38: =BC38*NF!G$6 -> 0 | CL38: =BD38*NF!H$6 -> 0 | CM38: =BE38*NF!I$6 -> 0 | ... DM38: =CE38*NF!AI$6 -> 1
A39: High | B39: Q9NY15 | C39: Stabilin-1 OS=Homo sapiens OX=9606 GN=STAB1 PE=1 SV=3 | D39: 0 | E39: 16.627 | F39: 1 | G39: 3 | H39: 8 | I39: 3 | J39: 2570 | K39: 275.3 | L39: 6.49 | M39: 14.86 | N39: 3 | O39: 0 | P39: 219.4 | Q39: 377 | R39: 254.3 | S39: 349.1 | T39: 326.9 | U39: 384.4 | V39: 423.5 | W39: 327.7 | X39: 388.4 | Y39: 366.6 | Z39: 392.4 | AA39: 354.6 | AB39: 296 | AC39: 398.1 | AD39: 433.9 | AE39: 296.2 | AF39: 400.3 | AG39: 27 | AH39: 37 | AI39: 25.7 | AJ39: 31 | AK39: 29.5 | AL39: 26.7 | AM39: 29.4 | AN39: 23.2 | AO39: 24.6 | AP39: 22.8 | AQ39: 24.7 | AR39: 20.8 | AS39: 22.6 | AT39: 21.3 | AU39: 28 | AV39: 25.5 | AW39: 28.6 | AX39: =P39/$AF39 -> 0.54808893 | AY39: =Q39/$AF39 -> 0.94179365 | AZ39: =R39/$AF39 -> 0.63527354 | BA39: =S39/$AF39 -> 0.87209593 | BB39: =T39/$AF39 -> 0.81663752 | BC39: =U39/$AF39 -> 0.96027979 | BD39: =V39/$AF39 -> 1.0579565 | BE39: =W39/$AF39 -> 0.81863602 | ... BN39: =AF39/$AF39 -> 1 | BO39: =AG39/$AW39 -> 0.94405594 | BP39: =AH39/$AW39 -> 1.2937063 | BQ39: =AI39/$AW39 -> 0.8986014 | BR39: =AJ39/$AW39 -> 1.0839161 | BS39: =AK39/$AW39 -> 1.0314685 | BT39: =AL39/$AW39 -> 0.93356643 | BU39: =AM39/$AW39 -> 1.027972 | BV39: =AN39/$AW39 -> 0.81118881 | ... CE39: =AW39/$AW39 -> 1 | CF39: =AX39*NF!B$6 -> 0.56103592 | CG39: =AY39*NF!C$6 -> 0.84690118 | CH39: =AZ39*NF!D$6 -> 0.57665388 | CI39: =BA39*NF!E$6 -> 0.72542712 | CJ39: =BB39*NF!F$6 -> 0.65703271 | CK39: =BC39*NF!G$6 -> 0.7134077 | CL39: =BD39*NF!H$6 -> 0.76606672 | CM39: =BE39*NF!I$6 -> 0.66438878 | ... DM39: =CE39*NF!AI$6 -> 1
A40: Low | B40: Q9Y4D8 | C40: Probable E3 ubiquitin-protein ligase HECTD4 OS=Homo sapiens OX=9606 GN=HECTD4 PE=1 SV=5 | D40: 0.256 | E40: 0.878 | F40: 0 | G40: 1 | H40: 2 | I40: 1 | J40: 3996 | K40: 439.1 | L40: 6.19 | M40: 0 | N40: 1 | O40: 0 | AG40: 27.7 | AH40: 32.2 | AI40: 23 | AJ40: 35.8 | AK40: 46.2 | AL40: 23.8 | AM40: 52.4 | AN40: 36.8 | AO40: 26.9 | AP40: 45.4 | AQ40: 30.7 | AR40: 21 | AS40: 25.9 | AT40: 21.7 | AU40: 25.6 | AV40: 27.5 | AW40: 25.2 | AX40: 0 | AY40: 0 | AZ40: 0 | BA40: 0 | BB40: 0 | BC40: 0 | BD40: 0 | BE40: 0 | BF40: 0 | BG40: 0 | BH40: 0 | BI40: 0 | BJ40: 0 | BK40: 0 | BL40: 0 | BM40: 0 | BN40: 0 | BO40: =AG40/$AW40 -> 1.0992063 | BP40: =AH40/$AW40 -> 1.2777778 | BQ40: =AI40/$AW40 -> 0.91269841 | BR40: =AJ40/$AW40 -> 1.4206349 | BS40: =AK40/$AW40 -> 1.8333333 | BT40: =AL40/$AW40 -> 0.94444444 | BU40: =AM40/$AW40 -> 2.0793651 | BV40: =AN40/$AW40 -> 1.4603175 | ... CE40: =AW40/$AW40 -> 1 | CF40: =AX40*NF!B$6 -> 0 | CG40: =AY40*NF!C$6 -> 0 | CH40: =AZ40*NF!D$6 -> 0 | CI40: =BA40*NF!E$6 -> 0 | CJ40: =BB40*NF!F$6 -> 0 | CK40: =BC40*NF!G$6 -> 0 | CL40: =BD40*NF!H$6 -> 0 | CM40: =BE40*NF!I$6 -> 0 | ... DM40: =CE40*NF!AI$6 -> 1
...

Sheet NF
A1: Sample name | B1: 001FEA | C1: 002FAA | D1: 003MEA | E1: 004FAA | F1: 005FEA | G1: 006FEA | H1: 007FEA | I1: 008MEA | J1: 009FEA | K1: 010MEA | L1: 011FEA | M1: 012FEA | N1: 013MEA | O1: 014MEA | P1: 015MEA | Q1: 016FEA | R1: master mix1 | S1: 017FEA | T1: 018MEA | U1: 019MEA | V1: 020MAA | W1: 021MAA | X1: 022MAA | Y1: 023MAA | Z1: 024FAA | AA1: 025FAA | AB1: 026MAA | AC1: 027FAA | AD1: 028FEA | AE1: 029FAA | AF1: 030MAA | AG1: 031MEA | AH1: 032FAA | AI1: master mix2
A2: TMT-tag | B2: 126 | C2: 127N | D2: 127C | E2: 128N | F2: 128C | G2: 129N | H2: 129C | I2: 130N | J2: 130C | K2: 131N | L2: 131C | M2: 132N | N2: 132C | O2: 133N | P2: 133C | Q2: 134N | R2: 134C | S2: 126 | T2: 127N | U2: 127C | V2: 128N | W2: 128C | X2: 129N | Y2: 129C | Z2: 130N | AA2: 130C | AB2: 131N | AC2: 131C | AD2: 132N | AE2: 132C | AF2: 132C | AG2: 132C | AH2: 134N | AI2: 134C
A3: sample | B3: Abundance: F1: 126, Sample | C3: Abundance: F1: 127N, Sample | D3: Abundance: F1: 127C, Sample | E3: Abundance: F1: 128N, Sample | F3: Abundance: F1: 128C, Sample | G3: Abundance: F1: 129N, Sample | H3: Abundance: F1: 129C, Sample | I3: Abundance: F1: 130N, Sample | J3: Abundance: F1: 130C, Sample | K3: Abundance: F1: 131N, Sample | L3: Abundance: F1: 131C, Sample | M3: Abundance: F1: 132N, Sample | N3: Abundance: F1: 132C, Sample | O3: Abundance: F1: 133N, Sample | P3: Abundance: F1: 133C, Sample | Q3: Abundance: F1: 134N, Sample | R3: Abundance: F1: 134C, Sample | S3: Abundance: F2: 126, Sample | T3: Abundance: F2: 127N, Sample | U3: Abundance: F2: 127C, Sample | V3: Abundance: F2: 128N, Sample | W3: Abundance: F2: 128C, Sample | X3: Abundance: F2: 129N, Sample | Y3: Abundance: F2: 129C, Sample | Z3: Abundance: F2: 130N, Sample | AA3: Abundance: F2: 130C, Sample | AB3: Abundance: F2: 131N, Sample | AC3: Abundance: F2: 131C, Sample | AD3: Abundance: F2: 132N, Sample | AE3: Abundance: F2: 132C, Sample | AF3: Abundance: F2: 133N, Sample | AG3: Abundance: F2: 133C, Sample | AH3: Abundance: F2: 134N, Sample | AI3: Abundance: F2: 134C, Sample
A4: summed ratio | B4: 973.9923 | C4: 1108.7106 | D4: 1098.3499 | E4: 1198.5761 | F4: 1239.1889 | G4: 1342.0082 | H4: 1376.8809 | I4: 1228.4676 | J4: 1278.4329 | K4: 1065.3694 | L4: 1578.3425 | M4: 929.01821 | N4: 934.32359 | O4: 1051.1949 | P4: 976.34663 | Q4: 1066.2013 | R4: 997 | S4: 1780.6275 | T4: 1817.7744 | U4: 1878.5315 | V4: 1676.8969 | W4: 1940.462 | X4: 1570.335 | Y4: 2027.5998 | Z4: 1435.4334 | AA4: 1404.4165 | AB4: 1439.7439 | AC4: 1329.3367 | AD4: 1288.7929 | AE4: 1262.716 | AF4: 1303.4482 | AG4: 1443.3649 | AH4: 1640.955 | AI4: 1239
A5: NF | B5: =$R$4/B4 -> 1.0236221 | C5: =$R$4/C4 -> 0.89924281 | D5: =$R$4/D4 -> 0.90772532 | E5: =$R$4/E4 -> 0.83182033 | F5: =$R$4/F4 -> 0.80455856 | G5: =$R$4/G4 -> 0.7429165 | H5: =$R$4/H4 -> 0.72410038 | I5: =$R$4/I4 -> 0.81158019 | ... R5: =$R$4/R4 -> 1 | S5: =$AI$4/S4 -> 0.69582212 | T5: =$AI$4/T4 -> 0.68160272 | U5: =$AI$4/U4 -> 0.65955774 | V5: =$AI$4/V4 -> 0.73886474 | W5: =$AI$4/W4 -> 0.63850775 | X5: =$AI$4/X4 -> 0.78900364 | Y5: =$AI$4/Y4 -> 0.61106732 | Z5: =$AI$4/Z4 -> 0.86315393 | ... AI5: =$AI$4/AI4 -> 1
